Workbook

Sheet ReadMe
A1: Landova Proforma v3
A2: Any U.S. parcel x every use x the active org. Parcel facts + location + use defaults + learned data -> what fits -> cost -> three exits -> max offer -> prefilled proforma.
A4: Start here
A5: 1. Parcel | B5: Enter the parcel's facts: state, county, city, zoning, access, utilities, asking price, location data.
A6: 2. Best_Use | B6: Is this land good, for what, and what can we pay? Every use ranked by max offer with a verdict. Switch to 'My uses' on Org_Profile.
A7: 3. Proforma | B7: The prefilled proforma for any use: inputs with their source, budget, operating statement, exits, monthly cash flow and IRR.
A9: What changed in v3
A10: Any location | B10: Regions holds National > State > County > City values. Location shows which level each value came from. Costs AND revenues are localized.
A11: Learning | B11: Org_Overrides and Cost_Records hold the org's own numbers from uploads and actuals. They pull values toward the org's experience as records accumulate (shrinkage).
A12: Market data | B12: Market_Data holds local comps and pooled benchmarks (pooled only counts with enough records and orgs).
A13: Gates | B13: Zoning (by right / rezone / prohibited / deed-restricted), legal access, frontage, sewer, water, location tests, size.
A14: Realism | B14: Demand caps, absorption-driven timelines, margin that rises with time, per-use site disturbance, gal/day septic limits, public-water-system threshold, permits.
A15: New uses | B15: Frontage split lots, ranchette subdivision, MHC with park-owned homes, leisure RV/campground, STR tiny-home resort, dollar store, car wash, sit-down restaurant, church, cell tower.
A17: How it is built
A18: Four engines | B18: For-Sale · Income (NOI / cap) · Operator Pad (sell or ground-lease a pad) · Land Play (leases, entitle-and-sell).
A19: Three exits | B19: 1) Land / pad sale 2) Build & sell 3) Build & hold / lease. Use_Library says which are allowed.
A20: Max offer | B20: Solves for the land price that leaves exactly the required margin, including costs that rise with land price (closing, conversion penalty, carry, financing, property tax).
A21: Engine | B21: One row per use, one column per step. This tab is the spec Ryan codes from.
A23: Color code
A24: Blue on yellow | B24: Input - edit
A25: Black | B25: Formula - don't edit
A26: Green | B26: Link to another tab
A28: Before using on a live deal
A29: Placeholders | B29: Every cost, price, rent, cap rate, index, tax rate and rule is a placeholder. Replace with sourced data, comps, bids and actuals.
A30: Low confidence | B30: Uses whose written location rules are not machine-tested are marked 'Low - verify location' and show the rule to check.

Sheet Parcel
A1: Parcel Inputs
A2: One parcel. In the software these fill from Landova's site analysis and data layers. Blue on yellow = input.
B4: Input | C4: Value | D4: Unit | E4: Source in Landova
B5: Parcel name | C5: Sample Parcel - Grayson County | E5: User
B6: State (2-letter) | C6: TX | D6: ST | E6: Parcel record
B7: County | C7: Grayson | E7: Parcel record
B8: City (blank if unincorporated) | E8: Jurisdiction layer
B9: Jurisdiction type | C9: County | D9: City/ETJ/County | E9: Jurisdiction layer
B10: Zoning classes allowed by right (comma list) | C10: AG | D10: classes | E10: Zoning layer + crosswalk
B11: Classes barred by deed restrictions (comma list) | D11: classes | E11: Title / deed-restriction scan
B12: Classes realistic by rezoning (comma list, * = any) | C12: * | D12: classes | E12: Comp plan / future land use map
B13: Cost scenario | C13: Base | D13: Low/Base/High | E13: User
B14: Gross acres | C14: 20 | D14: ac | E14: Parcel boundary
B15: Buildable % (excl. floodway, wetlands, easements, steep slope) | C15: 0.78 | D15: % of gross | E15: Buildable-land analysis
B16: Share in 100-yr floodplain | C16: 0.1 | D16: % of gross | E16: FEMA flood layer
B17: Average slope | C17: 0.04 | D17: % | E17: Topography
B18: Tree cover | C18: 0.35 | D18: % | E18: 3D tree coverage
B19: Road frontage | C19: 660 | D19: LF | E19: Frontage analysis
B20: Access | C20: Paved public | D20: type | E20: Road network / title
B21: Public water at site | C21: Y | D21: Y/N | E21: Utilities layer
B22: Distance to water main | C22: 0 | D22: LF | E22: Utilities layer
B23: Public sewer at site | C23: N | D23: Y/N | E23: Utilities layer
B24: Distance to sewer main | C24: 6000 | D24: LF | E24: Utilities layer
B25: Septic soil rating | C25: Fair | D25: Good/Fair/Poor | E25: Soil composition
B26: Ag / open-space valuation in place | C26: Y | D26: Y/N | E26: Appraisal district record
B27: Asking / offer price (whole parcel) | C27: 300000 | D27: $ | E27: Listing or user
B28: Traffic count on frontage road | C28: 4000 | D28: vehicles/day | E28: State DOT / FHWA counts
B29: Households within 3 miles | C29: 2500 | D29: households | E29: Census
B30: Households within 10 miles | C30: 25000 | D30: households | E30: Census
B31: Miles to nearest highway interchange | C31: 6 | D31: miles | E31: Road network
B32: Corner lot (hard corner on two roads) | C32: N | D32: Y/N | E32: Frontage analysis
B33: Miles to substation with capacity | C33: 3 | D33: miles | E33: Utility / transmission layer
B34: Miles to nearest major employer (1,000+ jobs) | C34: 12 | D34: miles | E34: Employer layer
B36: Derived (formulas)
B37: Net buildable acres | C37: =Parcel!$C$14*Parcel!$C$15
B38: Public water used (1 = yes) | C38: =IF(OR(Parcel!$C$21="Y",Parcel!$C$22<=Assumptions!$C$5),1,0)
B39: Public sewer used (1 = yes) | C39: =IF(OR(Parcel!$C$23="Y",Parcel!$C$24<=Assumptions!$C$6),1,0)
B40: Off-site water extension LF | C40: =IF(Parcel!$C$21="Y",0,Parcel!$C$22)*Parcel!$C$38
B41: Off-site sewer extension LF | C41: =IF(Parcel!$C$23="Y",0,Parcel!$C$24)*Parcel!$C$39
B42: Scenario column | C42: =MATCH(Parcel!$C$13,Lookups!$A$5:$A$7,0)
...

Sheet Best_Use
A1: Best Use - is this land good, for what, and what can we pay
A2: Every use in the library run against the parcel on the Parcel tab, localized to its county and the active org's numbers, ranked by max offer.
B4: Parcel | C4: =Parcel!$C$5 | E4: Best use | F4: =B13
B5: Location | C5: =Location!$C$34 | E5: Verdict | F5: =E13
B6: Asking price | C6: =Parcel!$C$27 | E6: Max offer (walk-away) | F6: =J13
B7: As-is value (raw land, location) | C7: =Parcel!$C$14*Location!$C$14 | E7: Opening offer | F7: =K13
B8: Ranking shows | C8: =Org_Profile!$C$5&" for "&Org_Profile!$C$4 | E8: Uses that work at asking | F8: =COUNTIF(Engine!$FA$6:$FA$67,"Strong")+COUNTIF(Engine!$FA$6:$FA$67,"Works at asking")
E9: Uses that work for this org | F9: =SUMPRODUCT((Engine!$FA$6:$FA$67="Strong")+(Engine!$FA$6:$FA$67="Works at asking"),Engine!$E$6:$E$67)
A12: Rank | B12: Use | C12: Engine | D12: Org builds | E12: Verdict | F12: Capacity | G12: Unit | H12: Best exit | I12: Months | J12: Max offer | K12: Opening offer | L12: Max - asking | M12: Max / gross ac | N12: Max / unit | O12: Confidence | P12: Binding constraint | Q12: Flags | R12: Verify before relying | S12: row
A13: 1 | B13: =INDEX(Engine!$A$6:$A$67,$S13) | C13: =INDEX(Engine!$B$6:$B$67,$S13) | D13: =INDEX(Engine!$E$6:$E$67,$S13) | E13: =INDEX(Engine!$FA$6:$FA$67,$S13) | F13: =INDEX(Engine!$AK$6:$AK$67,$S13) | G13: =INDEX(Engine!$C$6:$C$67,$S13) | H13: =INDEX(Engine!$EU$6:$EU$67,$S13) | I13: =INDEX(Engine!$EV$6:$EV$67,$S13) | J13: =INDEX(Engine!$ES$6:$ES$67,$S13) | K13: =INDEX(Engine!$EW$6:$EW$67,$S13) | L13: =INDEX(Engine!$EX$6:$EX$67,$S13) | M13: =INDEX(Engine!$EY$6:$EY$67,$S13) | N13: =INDEX(Engine!$EZ$6:$EZ$67,$S13) | O13: =INDEX(Engine!$FB$6:$FB$67,$S13) | P13: =INDEX(Engine!$AL$6:$AL$67,$S13) | Q13: =INDEX(Engine!$FD$6:$FD$67,$S13) | R13: =INDEX(Engine!$FC$6:$FC$67,$S13) | S13: =MATCH(LARGE(Engine!$FE$6:$FE$67,A13),Engine!$FE$6:$FE$67,0)
A14: 2 | B14: =INDEX(Engine!$A$6:$A$67,$S14) | C14: =INDEX(Engine!$B$6:$B$67,$S14) | D14: =INDEX(Engine!$E$6:$E$67,$S14) | E14: =INDEX(Engine!$FA$6:$FA$67,$S14) | F14: =INDEX(Engine!$AK$6:$AK$67,$S14) | G14: =INDEX(Engine!$C$6:$C$67,$S14) | H14: =INDEX(Engine!$EU$6:$EU$67,$S14) | I14: =INDEX(Engine!$EV$6:$EV$67,$S14) | J14: =INDEX(Engine!$ES$6:$ES$67,$S14) | K14: =INDEX(Engine!$EW$6:$EW$67,$S14) | L14: =INDEX(Engine!$EX$6:$EX$67,$S14) | M14: =INDEX(Engine!$EY$6:$EY$67,$S14) | N14: =INDEX(Engine!$EZ$6:$EZ$67,$S14) | O14: =INDEX(Engine!$FB$6:$FB$67,$S14) | P14: =INDEX(Engine!$AL$6:$AL$67,$S14) | Q14: =INDEX(Engine!$FD$6:$FD$67,$S14) | R14: =INDEX(Engine!$FC$6:$FC$67,$S14) | S14: =MATCH(LARGE(Engine!$FE$6:$FE$67,A14),Engine!$FE$6:$FE$67,0)
A15: 3 | B15: =INDEX(Engine!$A$6:$A$67,$S15) | C15: =INDEX(Engine!$B$6:$B$67,$S15) | D15: =INDEX(Engine!$E$6:$E$67,$S15) | E15: =INDEX(Engine!$FA$6:$FA$67,$S15) | F15: =INDEX(Engine!$AK$6:$AK$67,$S15) | G15: =INDEX(Engine!$C$6:$C$67,$S15) | H15: =INDEX(Engine!$EU$6:$EU$67,$S15) | I15: =INDEX(Engine!$EV$6:$EV$67,$S15) | J15: =INDEX(Engine!$ES$6:$ES$67,$S15) | K15: =INDEX(Engine!$EW$6:$EW$67,$S15) | L15: =INDEX(Engine!$EX$6:$EX$67,$S15) | M15: =INDEX(Engine!$EY$6:$EY$67,$S15) | N15: =INDEX(Engine!$EZ$6:$EZ$67,$S15) | O15: =INDEX(Engine!$FB$6:$FB$67,$S15) | P15: =INDEX(Engine!$AL$6:$AL$67,$S15) | Q15: =INDEX(Engine!$FD$6:$FD$67,$S15) | R15: =INDEX(Engine!$FC$6:$FC$67,$S15) | S15: =MATCH(LARGE(Engine!$FE$6:$FE$67,A15),Engine!$FE$6:$FE$67,0)
A16: 4 | B16: =INDEX(Engine!$A$6:$A$67,$S16) | C16: =INDEX(Engine!$B$6:$B$67,$S16) | D16: =INDEX(Engine!$E$6:$E$67,$S16) | E16: =INDEX(Engine!$FA$6:$FA$67,$S16) | F16: =INDEX(Engine!$AK$6:$AK$67,$S16) | G16: =INDEX(Engine!$C$6:$C$67,$S16) | H16: =INDEX(Engine!$EU$6:$EU$67,$S16) | I16: =INDEX(Engine!$EV$6:$EV$67,$S16) | J16: =INDEX(Engine!$ES$6:$ES$67,$S16) | K16: =INDEX(Engine!$EW$6:$EW$67,$S16) | L16: =INDEX(Engine!$EX$6:$EX$67,$S16) | M16: =INDEX(Engine!$EY$6:$EY$67,$S16) | N16: =INDEX(Engine!$EZ$6:$EZ$67,$S16) | O16: =INDEX(Engine!$FB$6:$FB$67,$S16) | P16: =INDEX(Engine!$AL$6:$AL$67,$S16) | Q16: =INDEX(Engine!$FD$6:$FD$67,$S16) | R16: =INDEX(Engine!$FC$6:$FC$67,$S16) | S16: =MATCH(LARGE(Engine!$FE$6:$FE$67,A16),Engine!$FE$6:$FE$67,0)
A17: 5 | B17: =INDEX(Engine!$A$6:$A$67,$S17) | C17: =INDEX(Engine!$B$6:$B$67,$S17) | D17: =INDEX(Engine!$E$6:$E$67,$S17) | E17: =INDEX(Engine!$FA$6:$FA$67,$S17) | F17: =INDEX(Engine!$AK$6:$AK$67,$S17) | G17: =INDEX(Engine!$C$6:$C$67,$S17) | H17: =INDEX(Engine!$EU$6:$EU$67,$S17) | I17: =INDEX(Engine!$EV$6:$EV$67,$S17) | J17: =INDEX(Engine!$ES$6:$ES$67,$S17) | K17: =INDEX(Engine!$EW$6:$EW$67,$S17) | L17: =INDEX(Engine!$EX$6:$EX$67,$S17) | M17: =INDEX(Engine!$EY$6:$EY$67,$S17) | N17: =INDEX(Engine!$EZ$6:$EZ$67,$S17) | O17: =INDEX(Engine!$FB$6:$FB$67,$S17) | P17: =INDEX(Engine!$AL$6:$AL$67,$S17) | Q17: =INDEX(Engine!$FD$6:$FD$67,$S17) | R17: =INDEX(Engine!$FC$6:$FC$67,$S17) | S17: =MATCH(LARGE(Engine!$FE$6:$FE$67,A17),Engine!$FE$6:$FE$67,0)
A18: 6 | B18: =INDEX(Engine!$A$6:$A$67,$S18) | C18: =INDEX(Engine!$B$6:$B$67,$S18) | D18: =INDEX(Engine!$E$6:$E$67,$S18) | E18: =INDEX(Engine!$FA$6:$FA$67,$S18) | F18: =INDEX(Engine!$AK$6:$AK$67,$S18) | G18: =INDEX(Engine!$C$6:$C$67,$S18) | H18: =INDEX(Engine!$EU$6:$EU$67,$S18) | I18: =INDEX(Engine!$EV$6:$EV$67,$S18) | J18: =INDEX(Engine!$ES$6:$ES$67,$S18) | K18: =INDEX(Engine!$EW$6:$EW$67,$S18) | L18: =INDEX(Engine!$EX$6:$EX$67,$S18) | M18: =INDEX(Engine!$EY$6:$EY$67,$S18) | N18: =INDEX(Engine!$EZ$6:$EZ$67,$S18) | O18: =INDEX(Engine!$FB$6:$FB$67,$S18) | P18: =INDEX(Engine!$AL$6:$AL$67,$S18) | Q18: =INDEX(Engine!$FD$6:$FD$67,$S18) | R18: =INDEX(Engine!$FC$6:$FC$67,$S18) | S18: =MATCH(LARGE(Engine!$FE$6:$FE$67,A18),Engine!$FE$6:$FE$67,0)
A19: 7 | B19: =INDEX(Engine!$A$6:$A$67,$S19) | C19: =INDEX(Engine!$B$6:$B$67,$S19) | D19: =INDEX(Engine!$E$6:$E$67,$S19) | E19: =INDEX(Engine!$FA$6:$FA$67,$S19) | F19: =INDEX(Engine!$AK$6:$AK$67,$S19) | G19: =INDEX(Engine!$C$6:$C$67,$S19) | H19: =INDEX(Engine!$EU$6:$EU$67,$S19) | I19: =INDEX(Engine!$EV$6:$EV$67,$S19) | J19: =INDEX(Engine!$ES$6:$ES$67,$S19) | K19: =INDEX(Engine!$EW$6:$EW$67,$S19) | L19: =INDEX(Engine!$EX$6:$EX$67,$S19) | M19: =INDEX(Engine!$EY$6:$EY$67,$S19) | N19: =INDEX(Engine!$EZ$6:$EZ$67,$S19) | O19: =INDEX(Engine!$FB$6:$FB$67,$S19) | P19: =INDEX(Engine!$AL$6:$AL$67,$S19) | Q19: =INDEX(Engine!$FD$6:$FD$67,$S19) | R19: =INDEX(Engine!$FC$6:$FC$67,$S19) | S19: =MATCH(LARGE(Engine!$FE$6:$FE$67,A19),Engine!$FE$6:$FE$67,0)
A20: 8 | B20: =INDEX(Engine!$A$6:$A$67,$S20) | C20: =INDEX(Engine!$B$6:$B$67,$S20) | D20: =INDEX(Engine!$E$6:$E$67,$S20) | E20: =INDEX(Engine!$FA$6:$FA$67,$S20) | F20: =INDEX(Engine!$AK$6:$AK$67,$S20) | G20: =INDEX(Engine!$C$6:$C$67,$S20) | H20: =INDEX(Engine!$EU$6:$EU$67,$S20) | I20: =INDEX(Engine!$EV$6:$EV$67,$S20) | J20: =INDEX(Engine!$ES$6:$ES$67,$S20) | K20: =INDEX(Engine!$EW$6:$EW$67,$S20) | L20: =INDEX(Engine!$EX$6:$EX$67,$S20) | M20: =INDEX(Engine!$EY$6:$EY$67,$S20) | N20: =INDEX(Engine!$EZ$6:$EZ$67,$S20) | O20: =INDEX(Engine!$FB$6:$FB$67,$S20) | P20: =INDEX(Engine!$AL$6:$AL$67,$S20) | Q20: =INDEX(Engine!$FD$6:$FD$67,$S20) | R20: =INDEX(Engine!$FC$6:$FC$67,$S20) | S20: =MATCH(LARGE(Engine!$FE$6:$FE$67,A20),Engine!$FE$6:$FE$67,0)
A21: 9 | B21: =INDEX(Engine!$A$6:$A$67,$S21) | C21: =INDEX(Engine!$B$6:$B$67,$S21) | D21: =INDEX(Engine!$E$6:$E$67,$S21) | E21: =INDEX(Engine!$FA$6:$FA$67,$S21) | F21: =INDEX(Engine!$AK$6:$AK$67,$S21) | G21: =INDEX(Engine!$C$6:$C$67,$S21) | H21: =INDEX(Engine!$EU$6:$EU$67,$S21) | I21: =INDEX(Engine!$EV$6:$EV$67,$S21) | J21: =INDEX(Engine!$ES$6:$ES$67,$S21) | K21: =INDEX(Engine!$EW$6:$EW$67,$S21) | L21: =INDEX(Engine!$EX$6:$EX$67,$S21) | M21: =INDEX(Engine!$EY$6:$EY$67,$S21) | N21: =INDEX(Engine!$EZ$6:$EZ$67,$S21) | O21: =INDEX(Engine!$FB$6:$FB$67,$S21) | P21: =INDEX(Engine!$AL$6:$AL$67,$S21) | Q21: =INDEX(Engine!$FD$6:$FD$67,$S21) | R21: =INDEX(Engine!$FC$6:$FC$67,$S21) | S21: =MATCH(LARGE(Engine!$FE$6:$FE$67,A21),Engine!$FE$6:$FE$67,0)
A22: 10 | B22: =INDEX(Engine!$A$6:$A$67,$S22) | C22: =INDEX(Engine!$B$6:$B$67,$S22) | D22: =INDEX(Engine!$E$6:$E$67,$S22) | E22: =INDEX(Engine!$FA$6:$FA$67,$S22) | F22: =INDEX(Engine!$AK$6:$AK$67,$S22) | G22: =INDEX(Engine!$C$6:$C$67,$S22) | H22: =INDEX(Engine!$EU$6:$EU$67,$S22) | I22: =INDEX(Engine!$EV$6:$EV$67,$S22) | J22: =INDEX(Engine!$ES$6:$ES$67,$S22) | K22: =INDEX(Engine!$EW$6:$EW$67,$S22) | L22: =INDEX(Engine!$EX$6:$EX$67,$S22) | M22: =INDEX(Engine!$EY$6:$EY$67,$S22) | N22: =INDEX(Engine!$EZ$6:$EZ$67,$S22) | O22: =INDEX(Engine!$FB$6:$FB$67,$S22) | P22: =INDEX(Engine!$AL$6:$AL$67,$S22) | Q22: =INDEX(Engine!$FD$6:$FD$67,$S22) | R22: =INDEX(Engine!$FC$6:$FC$67,$S22) | S22: =MATCH(LARGE(Engine!$FE$6:$FE$67,A22),Engine!$FE$6:$FE$67,0)
A23: 11 | B23: =INDEX(Engine!$A$6:$A$67,$S23) | C23: =INDEX(Engine!$B$6:$B$67,$S23) | D23: =INDEX(Engine!$E$6:$E$67,$S23) | E23: =INDEX(Engine!$FA$6:$FA$67,$S23) | F23: =INDEX(Engine!$AK$6:$AK$67,$S23) | G23: =INDEX(Engine!$C$6:$C$67,$S23) | H23: =INDEX(Engine!$EU$6:$EU$67,$S23) | I23: =INDEX(Engine!$EV$6:$EV$67,$S23) | J23: =INDEX(Engine!$ES$6:$ES$67,$S23) | K23: =INDEX(Engine!$EW$6:$EW$67,$S23) | L23: =INDEX(Engine!$EX$6:$EX$67,$S23) | M23: =INDEX(Engine!$EY$6:$EY$67,$S23) | N23: =INDEX(Engine!$EZ$6:$EZ$67,$S23) | O23: =INDEX(Engine!$FB$6:$FB$67,$S23) | P23: =INDEX(Engine!$AL$6:$AL$67,$S23) | Q23: =INDEX(Engine!$FD$6:$FD$67,$S23) | R23: =INDEX(Engine!$FC$6:$FC$67,$S23) | S23: =MATCH(LARGE(Engine!$FE$6:$FE$67,A23),Engine!$FE$6:$FE$67,0)
A24: 12 | B24: =INDEX(Engine!$A$6:$A$67,$S24) | C24: =INDEX(Engine!$B$6:$B$67,$S24) | D24: =INDEX(Engine!$E$6:$E$67,$S24) | E24: =INDEX(Engine!$FA$6:$FA$67,$S24) | F24: =INDEX(Engine!$AK$6:$AK$67,$S24) | G24: =INDEX(Engine!$C$6:$C$67,$S24) | H24: =INDEX(Engine!$EU$6:$EU$67,$S24) | I24: =INDEX(Engine!$EV$6:$EV$67,$S24) | J24: =INDEX(Engine!$ES$6:$ES$67,$S24) | K24: =INDEX(Engine!$EW$6:$EW$67,$S24) | L24: =INDEX(Engine!$EX$6:$EX$67,$S24) | M24: =INDEX(Engine!$EY$6:$EY$67,$S24) | N24: =INDEX(Engine!$EZ$6:$EZ$67,$S24) | O24: =INDEX(Engine!$FB$6:$FB$67,$S24) | P24: =INDEX(Engine!$AL$6:$AL$67,$S24) | Q24: =INDEX(Engine!$FD$6:$FD$67,$S24) | R24: =INDEX(Engine!$FC$6:$FC$67,$S24) | S24: =MATCH(LARGE(Engine!$FE$6:$FE$67,A24),Engine!$FE$6:$FE$67,0)
... A74: 62 | B74: =INDEX(Engine!$A$6:$A$67,$S74) | C74: =INDEX(Engine!$B$6:$B$67,$S74) | D74: =INDEX(Engine!$E$6:$E$67,$S74) | E74: =INDEX(Engine!$FA$6:$FA$67,$S74) | F74: =INDEX(Engine!$AK$6:$AK$67,$S74) | G74: =INDEX(Engine!$C$6:$C$67,$S74) | H74: =INDEX(Engine!$EU$6:$EU$67,$S74) | I74: =INDEX(Engine!$EV$6:$EV$67,$S74) | J74: =INDEX(Engine!$ES$6:$ES$67,$S74) | K74: =INDEX(Engine!$EW$6:$EW$67,$S74) | L74: =INDEX(Engine!$EX$6:$EX$67,$S74) | M74: =INDEX(Engine!$EY$6:$EY$67,$S74) | N74: =INDEX(Engine!$EZ$6:$EZ$67,$S74) | O74: =INDEX(Engine!$FB$6:$FB$67,$S74) | P74: =INDEX(Engine!$AL$6:$AL$67,$S74) | Q74: =INDEX(Engine!$FD$6:$FD$67,$S74) | R74: =INDEX(Engine!$FC$6:$FC$67,$S74) | S74: =MATCH(LARGE(Engine!$FE$6:$FE$67,A74),Engine!$FE$6:$FE$67,0)
B76: Read with care: every number is a placeholder until replaced by market data or the org's own records. Low confidence = the use has written location rules Landova does not test yet.

Sheet Proforma
A1: Prefilled Proforma - one use on this parcel
A2: Pick a use (defaults to the top-ranked one). Every line is prefilled from the engine and shows where its number came from. Emits the Canonical Proforma Schema.
B4: Use | C4: =Best_Use!B13 | E4: Verdict | F4: =INDEX(Engine!$FA$6:$FA$67,$C$7)
B5: Exit | C5: Best | E5: Max offer (walk-away) | F5: =INDEX(Engine!$ES$6:$ES$67,$C$7)
B6: Land price for cash flow (blank = opening offer) | E6: Opening offer | F6: =INDEX(Engine!$EW$6:$EW$67,$C$7)
B7: Engine row | C7: =MATCH(C4,Engine!$A$6:$A$67,0) | E7: Best exit | F7: =INDEX(Engine!$EU$6:$EU$67,$C$7)
B8: Exit used | C8: =IF(C5="Best",MAX(1,INDEX(Engine!$ET$6:$ET$67,$C$7)),MATCH(C5,{"Land / pad sale","Build & sell","Build & hold / lease"},0)) | E8: Confidence | F8: =INDEX(Engine!$FB$6:$FB$67,$C$7)
B9: Land price used | C9: =IF(C6="",INDEX(Engine!$EW$6:$EW$67,$C$7),C6) | E9: Flags | F9: =INDEX(Engine!$FD$6:$FD$67,$C$7)
B11: Inputs used and where they came from
B12: Input | C12: Value | D12: Source | E12: Canonical field
B13: Vertical cost per unit | C13: =INDEX(Use_Effective!$B$5:$B$66,$C$7) | D13: =INDEX(Use_Effective!$Q$5:$Q$66,$C$7) | E13: vert
B14: Entitlement & zoning $ (fixed, reference basis) | C14: =INDEX(Use_Effective!$C$5:$C$66,$C$7) | D14: =INDEX(Use_Effective!$R$5:$R$66,$C$7) | E14: entitle
B15: TI + leasing commissions per unit | C15: =INDEX(Use_Effective!$D$5:$D$66,$C$7) | D15: =INDEX(Use_Effective!$S$5:$S$66,$C$7) | E15: tilc
B16: Opex per unit per year, excl. tax | C16: =INDEX(Use_Effective!$E$5:$E$66,$C$7) | D16: =INDEX(Use_Effective!$T$5:$T$66,$C$7) | E16: opex
B17: Development months | C17: =INDEX(Use_Effective!$F$5:$F$66,$C$7) | D17: =INDEX(Use_Effective!$U$5:$U$66,$C$7) | E17: devmo
B18: Required margin (first 12 months) | C18: =INDEX(Use_Effective!$G$5:$G$66,$C$7) | D18: =INDEX(Use_Effective!$V$5:$V$66,$C$7) | E18: margin
B19: Lot sale price per unit (For-Sale) | C19: =INDEX(Use_Effective!$H$5:$H$66,$C$7) | D19: =INDEX(Use_Effective!$W$5:$W$66,$C$7) | E19: lotprice
B20: Finished sale price per unit (For-Sale) | C20: =INDEX(Use_Effective!$I$5:$I$66,$C$7) | D20: =INDEX(Use_Effective!$X$5:$X$66,$C$7) | E20: saleprice
B21: Land / pad sale price per acre (For-Sale: per gross lot acre, added to lot price) | C21: =INDEX(Use_Effective!$J$5:$J$66,$C$7) | D21: =INDEX(Use_Effective!$Y$5:$Y$66,$C$7) | E21: landac
B22: Rent per unit per year (Income) | C22: =INDEX(Use_Effective!$K$5:$K$66,$C$7) | D22: =INDEX(Use_Effective!$Z$5:$Z$66,$C$7) | E22: rent
B23: Ground / land lease rent per acre per year | C23: =INDEX(Use_Effective!$L$5:$L$66,$C$7) | D23: =INDEX(Use_Effective!$AA$5:$AA$66,$C$7) | E23: groundrent
B24: Exit / lease cap rate (reference basis) | C24: =INDEX(Use_Effective!$M$5:$M$66,$C$7) | D24: =INDEX(Use_Effective!$AB$5:$AB$66,$C$7) | E24: cap
B25: Stabilized vacancy (or 1 - occupancy for nightly uses) | C25: =INDEX(Use_Effective!$N$5:$N$66,$C$7) | D25: =INDEX(Use_Effective!$AC$5:$AC$66,$C$7) | E25: vac
B26: Absorption: units sold (For-Sale) or leased (Income) per month; 0 = use lease-up months | C26: =INDEX(Use_Effective!$O$5:$O$66,$C$7) | D26: =INDEX(Use_Effective!$AD$5:$AD$66,$C$7) | E26: absorb
B27: Exit 1 sell-out pace: lots (For-Sale) or acres (other) per month; 0 = single sale | C27: =INDEX(Use_Effective!$P$5:$P$66,$C$7) | D27: =INDEX(Use_Effective!$AE$5:$AE$66,$C$7) | E27: lotabs
B28: Location data level (cost index) | C28: =Location!$C$9 | D28: =Location!D9
B30: Site & yield
B31: Zoning status | C31: =INDEX(Engine!$J$6:$J$67,$C$7)
B32: Binding constraint | C32: =INDEX(Engine!$AL$6:$AL$67,$C$7)
B33: Usable acres (net - open space - detention) | C33: =INDEX(Engine!$F$6:$F$67,$C$7)
B34: Usable acres used by this use | C34: =INDEX(Engine!$AD$6:$AD$67,$C$7)
B35: Developed acres | C35: =INDEX(Engine!$AH$6:$AH$67,$C$7)
B36: Excess gross acres (resold as raw land) | C36: =INDEX(Engine!$AI$6:$AI$67,$C$7)
B37: CAPACITY (units / SF / acres) | C37: =INDEX(Engine!$AK$6:$AK$67,$C$7)
B38: Capacity unit | C38: =INDEX(Engine!$C$6:$C$67,$C$7)
B39: Development months (incl. rezoning / permits) | C39: =INDEX(Engine!$CO$6:$CO$67,$C$7)
B40: Exit 1 sell-out months | C40: =INDEX(Engine!$CP$6:$CP$67,$C$7)
B41: Exit 2 sell-out months (For-Sale) | C41: =INDEX(Engine!$CQ$6:$CQ$67,$C$7)
B42: Lease-up months (Income) | C42: =INDEX(Engine!$CR$6:$CR$67,$C$7)
B44: Development budget | C44: Full build budget. A lot / pad sale (exit 1) excludes paving, septic systems and wells - the buyer builds them.
...

Sheet Org_Profile
A1: Org Profile - who is looking
A2: The org's development types drive the 'My uses' ranking and the prefilled proformas. Learned values come from the org's uploads and actuals.
B4: Active org | C4: Ridge Stone Homes
B5: Ranking shows | C5: All uses
B7: Required margin by engine (blank = use library)
B8: Engine | C8: Org margin
B9: For-Sale
B10: Income
B11: Operator Pad
B12: Land Play
B14: Learned estimating bias (from Deal_History)
B15: Deals with actuals | C15: =COUNTIFS(Deal_History!$A$6:$A$305,Org_Profile!$C$4,Deal_History!$W$6:$W$305,">-10")
B16: Average cost overrun | C16: =IF(C15=0,0,SUMIFS(Deal_History!$W$6:$W$305,Deal_History!$A$6:$A$305,Org_Profile!$C$4)/C15)
B17: Bias applied (shrunk toward 0) | C17: =IF(C18="Y",SUMIFS(Deal_History!$W$6:$W$305,Deal_History!$A$6:$A$305,Org_Profile!$C$4)/(C15+Assumptions!$C$30),0)
B18: Apply bias to new runs | C18: Y
B20: Development types this org does
B21: Use | C21: I build this (Y/N)
B22: =Use_Library!$A$5 | C22: Y
B23: =Use_Library!$A$6 | C23: Y
B24: =Use_Library!$A$7 | C24: N
B25: =Use_Library!$A$8 | C25: N
B26: =Use_Library!$A$9 | C26: Y
B27: =Use_Library!$A$10 | C27: N
B28: =Use_Library!$A$11 | C28: Y
B29: =Use_Library!$A$12 | C29: Y
B30: =Use_Library!$A$13 | C30: N
B31: =Use_Library!$A$14 | C31: N
B32: =Use_Library!$A$15 | C32: N
B33: =Use_Library!$A$16 | C33: Y
B34: =Use_Library!$A$17 | C34: Y
B35: =Use_Library!$A$18 | C35: Y
B36: =Use_Library!$A$19 | C36: Y
B37: =Use_Library!$A$20 | C37: Y
B38: =Use_Library!$A$21 | C38: N
B39: =Use_Library!$A$22 | C39: N
B40: =Use_Library!$A$23 | C40: N
B41: =Use_Library!$A$24 | C41: N
B42: =Use_Library!$A$25 | C42: Y
B43: =Use_Library!$A$26 | C43: N
B44: =Use_Library!$A$27 | C44: N
...

Sheet Location
A1: Location - resolved values for this parcel
A2: Each value comes from the most specific level that has it: City > County > State > National. Source shows which level was used.
B4: City key | C4: =IF(Parcel!$C$8="","#none",Parcel!$C$6&"|"&Parcel!$C$7&"|"&Parcel!$C$8)
B5: County key | C5: =Parcel!$C$6&"|"&Parcel!$C$7
B6: State key | C6: =Parcel!$C$6
B8: Field | C8: Resolved value | D8: Source level
B9: Construction cost index | C9: =IF(IFERROR(INDEX(Regions!$D$5:$D$400,MATCH(Location!$C$4,Regions!$A$5:$A$400,0))<>"",FALSE),INDEX(Regions!$D$5:$D$400,MATCH(Location!$C$4,Regions!$A$5:$A$400,0)),IF(IFERROR(INDEX(Regions!$D$5:$D$400,MATCH(Location!$C$5,Regions!$A$5:$A$400,0))<>"",FALSE),INDEX(Regions!$D$5:$D$400,MATCH(Location!$C$5,Regions!$A$5:$A$400,0)),IF(IFERROR(INDEX(Regions!$D$5:$D$400,MATCH(Location!$C$6,Regions!$A$5:$A$400,0))<>"",FALSE),INDEX(Regions!$D$5:$D$400,MATCH(Location!$C$6,Regions!$A$5:$A$400,0)),INDEX(Regions!$D$5:$D$400,MATCH("US",Regions!$A$5:$A$400,0))))) | D9: =IF(IFERROR(INDEX(Regions!$D$5:$D$400,MATCH(Location!$C$4,Regions!$A$5:$A$400,0))<>"",FALSE),"City",IF(IFERROR(INDEX(Regions!$D$5:$D$400,MATCH(Location!$C$5,Regions!$A$5:$A$400,0))<>"",FALSE),"County",IF(IFERROR(INDEX(Regions!$D$5:$D$400,MATCH(Location!$C$6,Regions!$A$5:$A$400,0))<>"",FALSE),"State","National")))
B10: Sale price index (homes, lots, pads) | C10: =IF(IFERROR(INDEX(Regions!$E$5:$E$400,MATCH(Location!$C$4,Regions!$A$5:$A$400,0))<>"",FALSE),INDEX(Regions!$E$5:$E$400,MATCH(Location!$C$4,Regions!$A$5:$A$400,0)),IF(IFERROR(INDEX(Regions!$E$5:$E$400,MATCH(Location!$C$5,Regions!$A$5:$A$400,0))<>"",FALSE),INDEX(Regions!$E$5:$E$400,MATCH(Location!$C$5,Regions!$A$5:$A$400,0)),IF(IFERROR(INDEX(Regions!$E$5:$E$400,MATCH(Location!$C$6,Regions!$A$5:$A$400,0))<>"",FALSE),INDEX(Regions!$E$5:$E$400,MATCH(Location!$C$6,Regions!$A$5:$A$400,0)),INDEX(Regions!$E$5:$E$400,MATCH("US",Regions!$A$5:$A$400,0))))) | D10: =IF(IFERROR(INDEX(Regions!$E$5:$E$400,MATCH(Location!$C$4,Regions!$A$5:$A$400,0))<>"",FALSE),"City",IF(IFERROR(INDEX(Regions!$E$5:$E$400,MATCH(Location!$C$5,Regions!$A$5:$A$400,0))<>"",FALSE),"County",IF(IFERROR(INDEX(Regions!$E$5:$E$400,MATCH(Location!$C$6,Regions!$A$5:$A$400,0))<>"",FALSE),"State","National")))
B11: Rent index | C11: =IF(IFERROR(INDEX(Regions!$F$5:$F$400,MATCH(Location!$C$4,Regions!$A$5:$A$400,0))<>"",FALSE),INDEX(Regions!$F$5:$F$400,MATCH(Location!$C$4,Regions!$A$5:$A$400,0)),IF(IFERROR(INDEX(Regions!$F$5:$F$400,MATCH(Location!$C$5,Regions!$A$5:$A$400,0))<>"",FALSE),INDEX(Regions!$F$5:$F$400,MATCH(Location!$C$5,Regions!$A$5:$A$400,0)),IF(IFERROR(INDEX(Regions!$F$5:$F$400,MATCH(Location!$C$6,Regions!$A$5:$A$400,0))<>"",FALSE),INDEX(Regions!$F$5:$F$400,MATCH(Location!$C$6,Regions!$A$5:$A$400,0)),INDEX(Regions!$F$5:$F$400,MATCH("US",Regions!$A$5:$A$400,0))))) | D11: =IF(IFERROR(INDEX(Regions!$F$5:$F$400,MATCH(Location!$C$4,Regions!$A$5:$A$400,0))<>"",FALSE),"City",IF(IFERROR(INDEX(Regions!$F$5:$F$400,MATCH(Location!$C$5,Regions!$A$5:$A$400,0))<>"",FALSE),"County",IF(IFERROR(INDEX(Regions!$F$5:$F$400,MATCH(Location!$C$6,Regions!$A$5:$A$400,0))<>"",FALSE),"State","National")))
B12: Cap rate adjustment (+ = higher cap) | C12: =IF(IFERROR(INDEX(Regions!$G$5:$G$400,MATCH(Location!$C$4,Regions!$A$5:$A$400,0))<>"",FALSE),INDEX(Regions!$G$5:$G$400,MATCH(Location!$C$4,Regions!$A$5:$A$400,0)),IF(IFERROR(INDEX(Regions!$G$5:$G$400,MATCH(Location!$C$5,Regions!$A$5:$A$400,0))<>"",FALSE),INDEX(Regions!$G$5:$G$400,MATCH(Location!$C$5,Regions!$A$5:$A$400,0)),IF(IFERROR(INDEX(Regions!$G$5:$G$400,MATCH(Location!$C$6,Regions!$A$5:$A$400,0))<>"",FALSE),INDEX(Regions!$G$5:$G$400,MATCH(Location!$C$6,Regions!$A$5:$A$400,0)),INDEX(Regions!$G$5:$G$400,MATCH("US",Regions!$A$5:$A$400,0))))) | D12: =IF(IFERROR(INDEX(Regions!$G$5:$G$400,MATCH(Location!$C$4,Regions!$A$5:$A$400,0))<>"",FALSE),"City",IF(IFERROR(INDEX(Regions!$G$5:$G$400,MATCH(Location!$C$5,Regions!$A$5:$A$400,0))<>"",FALSE),"County",IF(IFERROR(INDEX(Regions!$G$5:$G$400,MATCH(Location!$C$6,Regions!$A$5:$A$400,0))<>"",FALSE),"State","National")))
B13: Opex index (insurance, utilities, labor) | C13: =IF(IFERROR(INDEX(Regions!$H$5:$H$400,MATCH(Location!$C$4,Regions!$A$5:$A$400,0))<>"",FALSE),INDEX(Regions!$H$5:$H$400,MATCH(Location!$C$4,Regions!$A$5:$A$400,0)),IF(IFERROR(INDEX(Regions!$H$5:$H$400,MATCH(Location!$C$5,Regions!$A$5:$A$400,0))<>"",FALSE),INDEX(Regions!$H$5:$H$400,MATCH(Location!$C$5,Regions!$A$5:$A$400,0)),IF(IFERROR(INDEX(Regions!$H$5:$H$400,MATCH(Location!$C$6,Regions!$A$5:$A$400,0))<>"",FALSE),INDEX(Regions!$H$5:$H$400,MATCH(Location!$C$6,Regions!$A$5:$A$400,0)),INDEX(Regions!$H$5:$H$400,MATCH("US",Regions!$A$5:$A$400,0))))) | D13: =IF(IFERROR(INDEX(Regions!$H$5:$H$400,MATCH(Location!$C$4,Regions!$A$5:$A$400,0))<>"",FALSE),"City",IF(IFERROR(INDEX(Regions!$H$5:$H$400,MATCH(Location!$C$5,Regions!$A$5:$A$400,0))<>"",FALSE),"County",IF(IFERROR(INDEX(Regions!$H$5:$H$400,MATCH(Location!$C$6,Regions!$A$5:$A$400,0))<>"",FALSE),"State","National")))
B14: Raw land value $ / acre | C14: =IF(IFERROR(INDEX(Regions!$I$5:$I$400,MATCH(Location!$C$4,Regions!$A$5:$A$400,0))<>"",FALSE),INDEX(Regions!$I$5:$I$400,MATCH(Location!$C$4,Regions!$A$5:$A$400,0)),IF(IFERROR(INDEX(Regions!$I$5:$I$400,MATCH(Location!$C$5,Regions!$A$5:$A$400,0))<>"",FALSE),INDEX(Regions!$I$5:$I$400,MATCH(Location!$C$5,Regions!$A$5:$A$400,0)),IF(IFERROR(INDEX(Regions!$I$5:$I$400,MATCH(Location!$C$6,Regions!$A$5:$A$400,0))<>"",FALSE),INDEX(Regions!$I$5:$I$400,MATCH(Location!$C$6,Regions!$A$5:$A$400,0)),INDEX(Regions!$I$5:$I$400,MATCH("US",Regions!$A$5:$A$400,0))))) | D14: =IF(IFERROR(INDEX(Regions!$I$5:$I$400,MATCH(Location!$C$4,Regions!$A$5:$A$400,0))<>"",FALSE),"City",IF(IFERROR(INDEX(Regions!$I$5:$I$400,MATCH(Location!$C$5,Regions!$A$5:$A$400,0))<>"",FALSE),"County",IF(IFERROR(INDEX(Regions!$I$5:$I$400,MATCH(Location!$C$6,Regions!$A$5:$A$400,0))<>"",FALSE),"State","National")))
B15: Property tax rate (all jurisdictions) | C15: =IF(IFERROR(INDEX(Regions!$J$5:$J$400,MATCH(Location!$C$4,Regions!$A$5:$A$400,0))<>"",FALSE),INDEX(Regions!$J$5:$J$400,MATCH(Location!$C$4,Regions!$A$5:$A$400,0)),IF(IFERROR(INDEX(Regions!$J$5:$J$400,MATCH(Location!$C$5,Regions!$A$5:$A$400,0))<>"",FALSE),INDEX(Regions!$J$5:$J$400,MATCH(Location!$C$5,Regions!$A$5:$A$400,0)),IF(IFERROR(INDEX(Regions!$J$5:$J$400,MATCH(Location!$C$6,Regions!$A$5:$A$400,0))<>"",FALSE),INDEX(Regions!$J$5:$J$400,MATCH(Location!$C$6,Regions!$A$5:$A$400,0)),INDEX(Regions!$J$5:$J$400,MATCH("US",Regions!$A$5:$A$400,0))))) | D15: =IF(IFERROR(INDEX(Regions!$J$5:$J$400,MATCH(Location!$C$4,Regions!$A$5:$A$400,0))<>"",FALSE),"City",IF(IFERROR(INDEX(Regions!$J$5:$J$400,MATCH(Location!$C$5,Regions!$A$5:$A$400,0))<>"",FALSE),"County",IF(IFERROR(INDEX(Regions!$J$5:$J$400,MATCH(Location!$C$6,Regions!$A$5:$A$400,0))<>"",FALSE),"State","National")))
B16: Assessed value as % of total cost | C16: =IF(IFERROR(INDEX(Regions!$K$5:$K$400,MATCH(Location!$C$4,Regions!$A$5:$A$400,0))<>"",FALSE),INDEX(Regions!$K$5:$K$400,MATCH(Location!$C$4,Regions!$A$5:$A$400,0)),IF(IFERROR(INDEX(Regions!$K$5:$K$400,MATCH(Location!$C$5,Regions!$A$5:$A$400,0))<>"",FALSE),INDEX(Regions!$K$5:$K$400,MATCH(Location!$C$5,Regions!$A$5:$A$400,0)),IF(IFERROR(INDEX(Regions!$K$5:$K$400,MATCH(Location!$C$6,Regions!$A$5:$A$400,0))<>"",FALSE),INDEX(Regions!$K$5:$K$400,MATCH(Location!$C$6,Regions!$A$5:$A$400,0)),INDEX(Regions!$K$5:$K$400,MATCH("US",Regions!$A$5:$A$400,0))))) | D16: =IF(IFERROR(INDEX(Regions!$K$5:$K$400,MATCH(Location!$C$4,Regions!$A$5:$A$400,0))<>"",FALSE),"City",IF(IFERROR(INDEX(Regions!$K$5:$K$400,MATCH(Location!$C$5,Regions!$A$5:$A$400,0))<>"",FALSE),"County",IF(IFERROR(INDEX(Regions!$K$5:$K$400,MATCH(Location!$C$6,Regions!$A$5:$A$400,0))<>"",FALSE),"State","National")))
B17: Buyer closing costs % of land | C17: =IF(IFERROR(INDEX(Regions!$L$5:$L$400,MATCH(Location!$C$4,Regions!$A$5:$A$400,0))<>"",FALSE),INDEX(Regions!$L$5:$L$400,MATCH(Location!$C$4,Regions!$A$5:$A$400,0)),IF(IFERROR(INDEX(Regions!$L$5:$L$400,MATCH(Location!$C$5,Regions!$A$5:$A$400,0))<>"",FALSE),INDEX(Regions!$L$5:$L$400,MATCH(Location!$C$5,Regions!$A$5:$A$400,0)),IF(IFERROR(INDEX(Regions!$L$5:$L$400,MATCH(Location!$C$6,Regions!$A$5:$A$400,0))<>"",FALSE),INDEX(Regions!$L$5:$L$400,MATCH(Location!$C$6,Regions!$A$5:$A$400,0)),INDEX(Regions!$L$5:$L$400,MATCH("US",Regions!$A$5:$A$400,0))))) | D17: =IF(IFERROR(INDEX(Regions!$L$5:$L$400,MATCH(Location!$C$4,Regions!$A$5:$A$400,0))<>"",FALSE),"City",IF(IFERROR(INDEX(Regions!$L$5:$L$400,MATCH(Location!$C$5,Regions!$A$5:$A$400,0))<>"",FALSE),"County",IF(IFERROR(INDEX(Regions!$L$5:$L$400,MATCH(Location!$C$6,Regions!$A$5:$A$400,0))<>"",FALSE),"State","National")))
B18: Seller transfer tax % of sale | C18: =IF(IFERROR(INDEX(Regions!$M$5:$M$400,MATCH(Location!$C$4,Regions!$A$5:$A$400,0))<>"",FALSE),INDEX(Regions!$M$5:$M$400,MATCH(Location!$C$4,Regions!$A$5:$A$400,0)),IF(IFERROR(INDEX(Regions!$M$5:$M$400,MATCH(Location!$C$5,Regions!$A$5:$A$400,0))<>"",FALSE),INDEX(Regions!$M$5:$M$400,MATCH(Location!$C$5,Regions!$A$5:$A$400,0)),IF(IFERROR(INDEX(Regions!$M$5:$M$400,MATCH(Location!$C$6,Regions!$A$5:$A$400,0))<>"",FALSE),INDEX(Regions!$M$5:$M$400,MATCH(Location!$C$6,Regions!$A$5:$A$400,0)),INDEX(Regions!$M$5:$M$400,MATCH("US",Regions!$A$5:$A$400,0))))) | D18: =IF(IFERROR(INDEX(Regions!$M$5:$M$400,MATCH(Location!$C$4,Regions!$A$5:$A$400,0))<>"",FALSE),"City",IF(IFERROR(INDEX(Regions!$M$5:$M$400,MATCH(Location!$C$5,Regions!$A$5:$A$400,0))<>"",FALSE),"County",IF(IFERROR(INDEX(Regions!$M$5:$M$400,MATCH(Location!$C$6,Regions!$A$5:$A$400,0))<>"",FALSE),"State","National")))
B19: Land carry % of land / yr (tax + insurance) | C19: =IF(IFERROR(INDEX(Regions!$N$5:$N$400,MATCH(Location!$C$4,Regions!$A$5:$A$400,0))<>"",FALSE),INDEX(Regions!$N$5:$N$400,MATCH(Location!$C$4,Regions!$A$5:$A$400,0)),IF(IFERROR(INDEX(Regions!$N$5:$N$400,MATCH(Location!$C$5,Regions!$A$5:$A$400,0))<>"",FALSE),INDEX(Regions!$N$5:$N$400,MATCH(Location!$C$5,Regions!$A$5:$A$400,0)),IF(IFERROR(INDEX(Regions!$N$5:$N$400,MATCH(Location!$C$6,Regions!$A$5:$A$400,0))<>"",FALSE),INDEX(Regions!$N$5:$N$400,MATCH(Location!$C$6,Regions!$A$5:$A$400,0)),INDEX(Regions!$N$5:$N$400,MATCH("US",Regions!$A$5:$A$400,0))))) | D19: =IF(IFERROR(INDEX(Regions!$N$5:$N$400,MATCH(Location!$C$4,Regions!$A$5:$A$400,0))<>"",FALSE),"City",IF(IFERROR(INDEX(Regions!$N$5:$N$400,MATCH(Location!$C$5,Regions!$A$5:$A$400,0))<>"",FALSE),"County",IF(IFERROR(INDEX(Regions!$N$5:$N$400,MATCH(Location!$C$6,Regions!$A$5:$A$400,0))<>"",FALSE),"State","National")))
B20: Ag/open-space conversion penalty % of land price | C20: =IF(IFERROR(INDEX(Regions!$O$5:$O$400,MATCH(Location!$C$4,Regions!$A$5:$A$400,0))<>"",FALSE),INDEX(Regions!$O$5:$O$400,MATCH(Location!$C$4,Regions!$A$5:$A$400,0)),IF(IFERROR(INDEX(Regions!$O$5:$O$400,MATCH(Location!$C$5,Regions!$A$5:$A$400,0))<>"",FALSE),INDEX(Regions!$O$5:$O$400,MATCH(Location!$C$5,Regions!$A$5:$A$400,0)),IF(IFERROR(INDEX(Regions!$O$5:$O$400,MATCH(Location!$C$6,Regions!$A$5:$A$400,0))<>"",FALSE),INDEX(Regions!$O$5:$O$400,MATCH(Location!$C$6,Regions!$A$5:$A$400,0)),INDEX(Regions!$O$5:$O$400,MATCH("US",Regions!$A$5:$A$400,0))))) | D20: =IF(IFERROR(INDEX(Regions!$O$5:$O$400,MATCH(Location!$C$4,Regions!$A$5:$A$400,0))<>"",FALSE),"City",IF(IFERROR(INDEX(Regions!$O$5:$O$400,MATCH(Location!$C$5,Regions!$A$5:$A$400,0))<>"",FALSE),"County",IF(IFERROR(INDEX(Regions!$O$5:$O$400,MATCH(Location!$C$6,Regions!$A$5:$A$400,0))<>"",FALSE),"State","National")))
B21: Impact / capital recovery fees $ per dwelling | C21: =IF(IFERROR(INDEX(Regions!$P$5:$P$400,MATCH(Location!$C$4,Regions!$A$5:$A$400,0))<>"",FALSE),INDEX(Regions!$P$5:$P$400,MATCH(Location!$C$4,Regions!$A$5:$A$400,0)),IF(IFERROR(INDEX(Regions!$P$5:$P$400,MATCH(Location!$C$5,Regions!$A$5:$A$400,0))<>"",FALSE),INDEX(Regions!$P$5:$P$400,MATCH(Location!$C$5,Regions!$A$5:$A$400,0)),IF(IFERROR(INDEX(Regions!$P$5:$P$400,MATCH(Location!$C$6,Regions!$A$5:$A$400,0))<>"",FALSE),INDEX(Regions!$P$5:$P$400,MATCH(Location!$C$6,Regions!$A$5:$A$400,0)),INDEX(Regions!$P$5:$P$400,MATCH("US",Regions!$A$5:$A$400,0))))) | D21: =IF(IFERROR(INDEX(Regions!$P$5:$P$400,MATCH(Location!$C$4,Regions!$A$5:$A$400,0))<>"",FALSE),"City",IF(IFERROR(INDEX(Regions!$P$5:$P$400,MATCH(Location!$C$5,Regions!$A$5:$A$400,0))<>"",FALSE),"County",IF(IFERROR(INDEX(Regions!$P$5:$P$400,MATCH(Location!$C$6,Regions!$A$5:$A$400,0))<>"",FALSE),"State","National")))
B22: Cities zone (Y/N) | C22: =IF(IFERROR(INDEX(Regions!$Q$5:$Q$400,MATCH(Location!$C$4,Regions!$A$5:$A$400,0))<>"",FALSE),INDEX(Regions!$Q$5:$Q$400,MATCH(Location!$C$4,Regions!$A$5:$A$400,0)),IF(IFERROR(INDEX(Regions!$Q$5:$Q$400,MATCH(Location!$C$5,Regions!$A$5:$A$400,0))<>"",FALSE),INDEX(Regions!$Q$5:$Q$400,MATCH(Location!$C$5,Regions!$A$5:$A$400,0)),IF(IFERROR(INDEX(Regions!$Q$5:$Q$400,MATCH(Location!$C$6,Regions!$A$5:$A$400,0))<>"",FALSE),INDEX(Regions!$Q$5:$Q$400,MATCH(Location!$C$6,Regions!$A$5:$A$400,0)),INDEX(Regions!$Q$5:$Q$400,MATCH("US",Regions!$A$5:$A$400,0))))) | D22: =IF(IFERROR(INDEX(Regions!$Q$5:$Q$400,MATCH(Location!$C$4,Regions!$A$5:$A$400,0))<>"",FALSE),"City",IF(IFERROR(INDEX(Regions!$Q$5:$Q$400,MATCH(Location!$C$5,Regions!$A$5:$A$400,0))<>"",FALSE),"County",IF(IFERROR(INDEX(Regions!$Q$5:$Q$400,MATCH(Location!$C$6,Regions!$A$5:$A$400,0))<>"",FALSE),"State","National")))
B23: ETJ / extraterritorial zoning (Y/N) | C23: =IF(IFERROR(INDEX(Regions!$R$5:$R$400,MATCH(Location!$C$4,Regions!$A$5:$A$400,0))<>"",FALSE),INDEX(Regions!$R$5:$R$400,MATCH(Location!$C$4,Regions!$A$5:$A$400,0)),IF(IFERROR(INDEX(Regions!$R$5:$R$400,MATCH(Location!$C$5,Regions!$A$5:$A$400,0))<>"",FALSE),INDEX(Regions!$R$5:$R$400,MATCH(Location!$C$5,Regions!$A$5:$A$400,0)),IF(IFERROR(INDEX(Regions!$R$5:$R$400,MATCH(Location!$C$6,Regions!$A$5:$A$400,0))<>"",FALSE),INDEX(Regions!$R$5:$R$400,MATCH(Location!$C$6,Regions!$A$5:$A$400,0)),INDEX(Regions!$R$5:$R$400,MATCH("US",Regions!$A$5:$A$400,0))))) | D23: =IF(IFERROR(INDEX(Regions!$R$5:$R$400,MATCH(Location!$C$4,Regions!$A$5:$A$400,0))<>"",FALSE),"City",IF(IFERROR(INDEX(Regions!$R$5:$R$400,MATCH(Location!$C$5,Regions!$A$5:$A$400,0))<>"",FALSE),"County",IF(IFERROR(INDEX(Regions!$R$5:$R$400,MATCH(Location!$C$6,Regions!$A$5:$A$400,0))<>"",FALSE),"State","National")))
B24: Counties zone unincorporated land (Y/N) | C24: =IF(IFERROR(INDEX(Regions!$S$5:$S$400,MATCH(Location!$C$4,Regions!$A$5:$A$400,0))<>"",FALSE),INDEX(Regions!$S$5:$S$400,MATCH(Location!$C$4,Regions!$A$5:$A$400,0)),IF(IFERROR(INDEX(Regions!$S$5:$S$400,MATCH(Location!$C$5,Regions!$A$5:$A$400,0))<>"",FALSE),INDEX(Regions!$S$5:$S$400,MATCH(Location!$C$5,Regions!$A$5:$A$400,0)),IF(IFERROR(INDEX(Regions!$S$5:$S$400,MATCH(Location!$C$6,Regions!$A$5:$A$400,0))<>"",FALSE),INDEX(Regions!$S$5:$S$400,MATCH(Location!$C$6,Regions!$A$5:$A$400,0)),INDEX(Regions!$S$5:$S$400,MATCH("US",Regions!$A$5:$A$400,0))))) | D24: =IF(IFERROR(INDEX(Regions!$S$5:$S$400,MATCH(Location!$C$4,Regions!$A$5:$A$400,0))<>"",FALSE),"City",IF(IFERROR(INDEX(Regions!$S$5:$S$400,MATCH(Location!$C$5,Regions!$A$5:$A$400,0))<>"",FALSE),"County",IF(IFERROR(INDEX(Regions!$S$5:$S$400,MATCH(Location!$C$6,Regions!$A$5:$A$400,0))<>"",FALSE),"State","National")))
B25: Min septic lot, public water (ac) | C25: =IF(IFERROR(INDEX(Regions!$T$5:$T$400,MATCH(Location!$C$4,Regions!$A$5:$A$400,0))<>"",FALSE),INDEX(Regions!$T$5:$T$400,MATCH(Location!$C$4,Regions!$A$5:$A$400,0)),IF(IFERROR(INDEX(Regions!$T$5:$T$400,MATCH(Location!$C$5,Regions!$A$5:$A$400,0))<>"",FALSE),INDEX(Regions!$T$5:$T$400,MATCH(Location!$C$5,Regions!$A$5:$A$400,0)),IF(IFERROR(INDEX(Regions!$T$5:$T$400,MATCH(Location!$C$6,Regions!$A$5:$A$400,0))<>"",FALSE),INDEX(Regions!$T$5:$T$400,MATCH(Location!$C$6,Regions!$A$5:$A$400,0)),INDEX(Regions!$T$5:$T$400,MATCH("US",Regions!$A$5:$A$400,0))))) | D25: =IF(IFERROR(INDEX(Regions!$T$5:$T$400,MATCH(Location!$C$4,Regions!$A$5:$A$400,0))<>"",FALSE),"City",IF(IFERROR(INDEX(Regions!$T$5:$T$400,MATCH(Location!$C$5,Regions!$A$5:$A$400,0))<>"",FALSE),"County",IF(IFERROR(INDEX(Regions!$T$5:$T$400,MATCH(Location!$C$6,Regions!$A$5:$A$400,0))<>"",FALSE),"State","National")))
B26: Min septic lot, private well (ac) | C26: =IF(IFERROR(INDEX(Regions!$U$5:$U$400,MATCH(Location!$C$4,Regions!$A$5:$A$400,0))<>"",FALSE),INDEX(Regions!$U$5:$U$400,MATCH(Location!$C$4,Regions!$A$5:$A$400,0)),IF(IFERROR(INDEX(Regions!$U$5:$U$400,MATCH(Location!$C$5,Regions!$A$5:$A$400,0))<>"",FALSE),INDEX(Regions!$U$5:$U$400,MATCH(Location!$C$5,Regions!$A$5:$A$400,0)),IF(IFERROR(INDEX(Regions!$U$5:$U$400,MATCH(Location!$C$6,Regions!$A$5:$A$400,0))<>"",FALSE),INDEX(Regions!$U$5:$U$400,MATCH(Location!$C$6,Regions!$A$5:$A$400,0)),INDEX(Regions!$U$5:$U$400,MATCH("US",Regions!$A$5:$A$400,0))))) | D26: =IF(IFERROR(INDEX(Regions!$U$5:$U$400,MATCH(Location!$C$4,Regions!$A$5:$A$400,0))<>"",FALSE),"City",IF(IFERROR(INDEX(Regions!$U$5:$U$400,MATCH(Location!$C$5,Regions!$A$5:$A$400,0))<>"",FALSE),"County",IF(IFERROR(INDEX(Regions!$U$5:$U$400,MATCH(Location!$C$6,Regions!$A$5:$A$400,0))<>"",FALSE),"State","National")))
B27: On-site septic capacity, gal/day per usable acre (good soil) | C27: =IF(IFERROR(INDEX(Regions!$V$5:$V$400,MATCH(Location!$C$4,Regions!$A$5:$A$400,0))<>"",FALSE),INDEX(Regions!$V$5:$V$400,MATCH(Location!$C$4,Regions!$A$5:$A$400,0)),IF(IFERROR(INDEX(Regions!$V$5:$V$400,MATCH(Location!$C$5,Regions!$A$5:$A$400,0))<>"",FALSE),INDEX(Regions!$V$5:$V$400,MATCH(Location!$C$5,Regions!$A$5:$A$400,0)),IF(IFERROR(INDEX(Regions!$V$5:$V$400,MATCH(Location!$C$6,Regions!$A$5:$A$400,0))<>"",FALSE),INDEX(Regions!$V$5:$V$400,MATCH(Location!$C$6,Regions!$A$5:$A$400,0)),INDEX(Regions!$V$5:$V$400,MATCH("US",Regions!$A$5:$A$400,0))))) | D27: =IF(IFERROR(INDEX(Regions!$V$5:$V$400,MATCH(Location!$C$4,Regions!$A$5:$A$400,0))<>"",FALSE),"City",IF(IFERROR(INDEX(Regions!$V$5:$V$400,MATCH(Location!$C$5,Regions!$A$5:$A$400,0))<>"",FALSE),"County",IF(IFERROR(INDEX(Regions!$V$5:$V$400,MATCH(Location!$C$6,Regions!$A$5:$A$400,0))<>"",FALSE),"State","National")))
B28: Wastewater flow needing a state permit (gal/day) | C28: =IF(IFERROR(INDEX(Regions!$W$5:$W$400,MATCH(Location!$C$4,Regions!$A$5:$A$400,0))<>"",FALSE),INDEX(Regions!$W$5:$W$400,MATCH(Location!$C$4,Regions!$A$5:$A$400,0)),IF(IFERROR(INDEX(Regions!$W$5:$W$400,MATCH(Location!$C$5,Regions!$A$5:$A$400,0))<>"",FALSE),INDEX(Regions!$W$5:$W$400,MATCH(Location!$C$5,Regions!$A$5:$A$400,0)),IF(IFERROR(INDEX(Regions!$W$5:$W$400,MATCH(Location!$C$6,Regions!$A$5:$A$400,0))<>"",FALSE),INDEX(Regions!$W$5:$W$400,MATCH(Location!$C$6,Regions!$A$5:$A$400,0)),INDEX(Regions!$W$5:$W$400,MATCH("US",Regions!$A$5:$A$400,0))))) | D28: =IF(IFERROR(INDEX(Regions!$W$5:$W$400,MATCH(Location!$C$4,Regions!$A$5:$A$400,0))<>"",FALSE),"City",IF(IFERROR(INDEX(Regions!$W$5:$W$400,MATCH(Location!$C$5,Regions!$A$5:$A$400,0))<>"",FALSE),"County",IF(IFERROR(INDEX(Regions!$W$5:$W$400,MATCH(Location!$C$6,Regions!$A$5:$A$400,0))<>"",FALSE),"State","National")))
B29: State wastewater permit months | C29: =IF(IFERROR(INDEX(Regions!$X$5:$X$400,MATCH(Location!$C$4,Regions!$A$5:$A$400,0))<>"",FALSE),INDEX(Regions!$X$5:$X$400,MATCH(Location!$C$4,Regions!$A$5:$A$400,0)),IF(IFERROR(INDEX(Regions!$X$5:$X$400,MATCH(Location!$C$5,Regions!$A$5:$A$400,0))<>"",FALSE),INDEX(Regions!$X$5:$X$400,MATCH(Location!$C$5,Regions!$A$5:$A$400,0)),IF(IFERROR(INDEX(Regions!$X$5:$X$400,MATCH(Location!$C$6,Regions!$A$5:$A$400,0))<>"",FALSE),INDEX(Regions!$X$5:$X$400,MATCH(Location!$C$6,Regions!$A$5:$A$400,0)),INDEX(Regions!$X$5:$X$400,MATCH("US",Regions!$A$5:$A$400,0))))) | D29: =IF(IFERROR(INDEX(Regions!$X$5:$X$400,MATCH(Location!$C$4,Regions!$A$5:$A$400,0))<>"",FALSE),"City",IF(IFERROR(INDEX(Regions!$X$5:$X$400,MATCH(Location!$C$5,Regions!$A$5:$A$400,0))<>"",FALSE),"County",IF(IFERROR(INDEX(Regions!$X$5:$X$400,MATCH(Location!$C$6,Regions!$A$5:$A$400,0))<>"",FALSE),"State","National")))
B30: Connections that make a public water system | C30: =IF(IFERROR(INDEX(Regions!$Y$5:$Y$400,MATCH(Location!$C$4,Regions!$A$5:$A$400,0))<>"",FALSE),INDEX(Regions!$Y$5:$Y$400,MATCH(Location!$C$4,Regions!$A$5:$A$400,0)),IF(IFERROR(INDEX(Regions!$Y$5:$Y$400,MATCH(Location!$C$5,Regions!$A$5:$A$400,0))<>"",FALSE),INDEX(Regions!$Y$5:$Y$400,MATCH(Location!$C$5,Regions!$A$5:$A$400,0)),IF(IFERROR(INDEX(Regions!$Y$5:$Y$400,MATCH(Location!$C$6,Regions!$A$5:$A$400,0))<>"",FALSE),INDEX(Regions!$Y$5:$Y$400,MATCH(Location!$C$6,Regions!$A$5:$A$400,0)),INDEX(Regions!$Y$5:$Y$400,MATCH("US",Regions!$A$5:$A$400,0))))) | D30: =IF(IFERROR(INDEX(Regions!$Y$5:$Y$400,MATCH(Location!$C$4,Regions!$A$5:$A$400,0))<>"",FALSE),"City",IF(IFERROR(INDEX(Regions!$Y$5:$Y$400,MATCH(Location!$C$5,Regions!$A$5:$A$400,0))<>"",FALSE),"County",IF(IFERROR(INDEX(Regions!$Y$5:$Y$400,MATCH(Location!$C$6,Regions!$A$5:$A$400,0))<>"",FALSE),"State","National")))
B31: Rezoning cost $ | C31: =IF(IFERROR(INDEX(Regions!$Z$5:$Z$400,MATCH(Location!$C$4,Regions!$A$5:$A$400,0))<>"",FALSE),INDEX(Regions!$Z$5:$Z$400,MATCH(Location!$C$4,Regions!$A$5:$A$400,0)),IF(IFERROR(INDEX(Regions!$Z$5:$Z$400,MATCH(Location!$C$5,Regions!$A$5:$A$400,0))<>"",FALSE),INDEX(Regions!$Z$5:$Z$400,MATCH(Location!$C$5,Regions!$A$5:$A$400,0)),IF(IFERROR(INDEX(Regions!$Z$5:$Z$400,MATCH(Location!$C$6,Regions!$A$5:$A$400,0))<>"",FALSE),INDEX(Regions!$Z$5:$Z$400,MATCH(Location!$C$6,Regions!$A$5:$A$400,0)),INDEX(Regions!$Z$5:$Z$400,MATCH("US",Regions!$A$5:$A$400,0))))) | D31: =IF(IFERROR(INDEX(Regions!$Z$5:$Z$400,MATCH(Location!$C$4,Regions!$A$5:$A$400,0))<>"",FALSE),"City",IF(IFERROR(INDEX(Regions!$Z$5:$Z$400,MATCH(Location!$C$5,Regions!$A$5:$A$400,0))<>"",FALSE),"County",IF(IFERROR(INDEX(Regions!$Z$5:$Z$400,MATCH(Location!$C$6,Regions!$A$5:$A$400,0))<>"",FALSE),"State","National")))
B32: Rezoning months | C32: =IF(IFERROR(INDEX(Regions!$AA$5:$AA$400,MATCH(Location!$C$4,Regions!$A$5:$A$400,0))<>"",FALSE),INDEX(Regions!$AA$5:$AA$400,MATCH(Location!$C$4,Regions!$A$5:$A$400,0)),IF(IFERROR(INDEX(Regions!$AA$5:$AA$400,MATCH(Location!$C$5,Regions!$A$5:$A$400,0))<>"",FALSE),INDEX(Regions!$AA$5:$AA$400,MATCH(Location!$C$5,Regions!$A$5:$A$400,0)),IF(IFERROR(INDEX(Regions!$AA$5:$AA$400,MATCH(Location!$C$6,Regions!$A$5:$A$400,0))<>"",FALSE),INDEX(Regions!$AA$5:$AA$400,MATCH(Location!$C$6,Regions!$A$5:$A$400,0)),INDEX(Regions!$AA$5:$AA$400,MATCH("US",Regions!$A$5:$A$400,0))))) | D32: =IF(IFERROR(INDEX(Regions!$AA$5:$AA$400,MATCH(Location!$C$4,Regions!$A$5:$A$400,0))<>"",FALSE),"City",IF(IFERROR(INDEX(Regions!$AA$5:$AA$400,MATCH(Location!$C$5,Regions!$A$5:$A$400,0))<>"",FALSE),"County",IF(IFERROR(INDEX(Regions!$AA$5:$AA$400,MATCH(Location!$C$6,Regions!$A$5:$A$400,0))<>"",FALSE),"State","National")))
B34: Location name | C34: =IF(Parcel!$C$8<>"",Parcel!$C$8&", ","")&Parcel!$C$7&" County, "&Parcel!$C$6&" (cost index from "&LOWER(D9)&" data)"

Sheet Use_Library
A1: Use Library
A2: One row per use, at the REFERENCE BASIS (index 1.0 = Grayson County, TX). The engine localizes and learns through Use_Effective. Every economic value is a PLACEHOLDER.
A4: Use | B4: Category | C4: Engine | D4: Capacity unit | E4: Discrete units (Y/N) | F4: Zoning class (see Lookups) | G4: Max density (units / net ac; 0 = n/a) | H4: Site SF per unit (0 = n/a) | I4: Min lot size, gross ac per unit (0 = n/a) | J4: Road frontage LF per unit (0 = n/a) | K4: Subdivided lots: septic min-lot rule applies (Y/N) | L4: Min usable acres needed (0 = none) | M4: Max usable acres market supports (0 = no cap) | N4: Open space % of net | O4: Demand per household in trade area (capacity units / HH; 0 = no cap) | P4: Trade area (3 or 10 mi) | Q4: Share of trade-area demand we capture | R4: Absorption: units sold (For-Sale) or leased (Income) per month; 0 = use lease-up months | S4: Exit 1 sell-out pace: lots (For-Sale) or acres (other) per month; 0 = single sale | T4: Requires public sewer (Y/N) | U4: Requires public water (Y/N) | V4: Utility taps / connections per unit | W4: Septic systems per unit (if no sewer) | X4: Private wells per unit (if no public water and below public-water-system threshold) | Y4: Wastewater gallons per day per unit | Z4: Horizontal work by us (Y/N) | AA4: Share of developed acres cleared / graded | AB4: Detention required (Y/N) | AC4: Road / drive LF per unit | AD4: Paving SF per unit | AE4: Entitlement & zoning $ (fixed, reference basis) | AF4: Vertical cost per unit | AG4: TI + leasing commissions per unit | AH4: Development months | AI4: Lot sale price per unit (For-Sale) | AJ4: Finished sale price per unit (For-Sale) | AK4: Rent per unit per year (Income) | AL4: Other income % of rent | AM4: Stabilized vacancy (or 1 - occupancy for nightly uses) | AN4: Opex per unit per year, excl. tax | AO4: Management % of EGI | AP4: Expense recovery % (NNN) | AQ4: Minimum lease-up months | AR4: Exit / lease cap rate (reference basis) | AS4: Land / pad sale price per acre (For-Sale: per gross lot acre, added to lot price) | AT4: Ground / land lease rent per acre per year | AU4: Required margin (first 12 months) | AV4: Exit allowed: Land / pad sale (1/0) | AW4: Exit allowed: Build & sell (1/0) | AX4: Exit allowed: Build & hold / lease (1/0) | AY4: Min road frontage LF | AZ4: Frontage minimum is a hard gate (Y/N) | BA4: Needs public road access (Y/N) | BB4: Min traffic count on frontage (VPD; 0 = none) | BC4: Min households within 3 mi (0 = none) | BD4: Max miles to highway interchange (0 = none) | BE4: Corner lot required (Y/N) | BF4: Max miles to substation w/ capacity (0 = none) | BG4: Max miles to major employer / anchor (0 = none) | BH4: Location notes fully machine-tested (Y/N) | BI4: Location requirements (land-search filters) | BJ4: Notes
A5: Homesites (stick-built, for sale) | B5: Housing | C5: For-Sale | D5: lot / home | E5: Y | F5: RES-SF | G5: 4 | H5: 0 | I5: 0 | J5: 0 | K5: Y | L5: 0 | M5: 0 | N5: 0.05 | O5: 0 | P5: 3 | Q5: 0 | R5: 3 | S5: 4 | T5: N | U5: N | V5: 1 | W5: 1 | X5: 1 | Y5: 300 | Z5: Y | AA5: 1 | AB5: Y | AC5: 50 | AD5: 0 | AE5: 25000 | AF5: 245000 | AG5: 0 | AH5: 12 | AI5: 80000 | AJ5: 375000 | AK5: 0 | AL5: 0 | AM5: 0 | AN5: 0 | AO5: 0 | AP5: 0 | AQ5: 0 | AR5: 0.07 | AS5: 0 | AT5: 0 | AU5: 0.15 | AV5: 1 | AW5: 1 | AX5: 0 | AY5: 60 | AZ5: N | BA5: Y | BB5: 0 | BC5: 0 | BD5: 0 | BE5: N | BF5: 0 | BG5: 0 | BH5: N | BI5: Within growth area; school district; < 30 min to job centers; no deed restriction on lot size | BJ5: Placeholder values
A6: Finished / entitled lots | B6: Housing | C6: For-Sale | D6: lot | E6: Y | F6: RES-SF | G6: 4 | H6: 0 | I6: 0 | J6: 0 | K6: Y | L6: 0 | M6: 0 | N6: 0.05 | O6: 0 | P6: 3 | Q6: 0 | R6: 3 | S6: 4 | T6: N | U6: N | V6: 1 | W6: 1 | X6: 1 | Y6: 300 | Z6: Y | AA6: 1 | AB6: Y | AC6: 50 | AD6: 0 | AE6: 25000 | AF6: 0 | AG6: 0 | AH6: 12 | AI6: 75000 | AJ6: 0 | AK6: 0 | AL6: 0 | AM6: 0 | AN6: 0 | AO6: 0 | AP6: 0 | AQ6: 0 | AR6: 0.07 | AS6: 0 | AT6: 0 | AU6: 0.15 | AV6: 1 | AW6: 0 | AX6: 0 | AY6: 60 | AZ6: N | BA6: Y | BB6: 0 | BC6: 0 | BD6: 0 | BE6: N | BF6: 0 | BG6: 0 | BH6: N | BI6: Builder demand in submarket; utilities within reach; platting allowed | BJ6: Placeholder values
A7: Active-adult 55+ (for sale) | B7: Housing | C7: For-Sale | D7: lot / home | E7: Y | F7: RES-SF | G7: 5 | H7: 0 | I7: 0 | J7: 0 | K7: Y | L7: 0 | M7: 0 | N7: 0.05 | O7: 0 | P7: 3 | Q7: 0 | R7: 2 | S7: 3 | T7: N | U7: N | V7: 1 | W7: 1 | X7: 1 | Y7: 300 | Z7: Y | AA7: 1 | AB7: Y | AC7: 45 | AD7: 0 | AE7: 25000 | AF7: 230000 | AG7: 0 | AH7: 12 | AI7: 70000 | AJ7: 360000 | AK7: 0 | AL7: 0 | AM7: 0 | AN7: 0 | AO7: 0 | AP7: 0 | AQ7: 0 | AR7: 0.07 | AS7: 0 | AT7: 0 | AU7: 0.15 | AV7: 1 | AW7: 1 | AX7: 0 | AY7: 60 | AZ7: N | BA7: Y | BB7: 0 | BC7: 0 | BD7: 0 | BE7: N | BF7: 0 | BG7: 0 | BH7: N | BI7: Near healthcare, retail and lakes/golf; 60+ population growth | BJ7: Placeholder values
A8: Entry-level for-sale homes | B8: Housing | C8: For-Sale | D8: lot / home | E8: Y | F8: RES-SF | G8: 5 | H8: 0 | I8: 0 | J8: 0 | K8: Y | L8: 0 | M8: 0 | N8: 0.05 | O8: 0 | P8: 3 | Q8: 0 | R8: 4 | S8: 5 | T8: N | U8: N | V8: 1 | W8: 1 | X8: 1 | Y8: 300 | Z8: Y | AA8: 1 | AB8: Y | AC8: 45 | AD8: 0 | AE8: 25000 | AF8: 210000 | AG8: 0 | AH8: 12 | AI8: 65000 | AJ8: 310000 | AK8: 0 | AL8: 0 | AM8: 0 | AN8: 0 | AO8: 0 | AP8: 0 | AQ8: 0 | AR8: 0.07 | AS8: 0 | AT8: 0 | AU8: 0.15 | AV8: 1 | AW8: 1 | AX8: 0 | AY8: 60 | AZ8: N | BA8: Y | BB8: 0 | BC8: 0 | BD8: 0 | BE8: N | BF8: 0 | BG8: 0 | BH8: N | BI8: Workforce demand (job growth); price-point gap vs. resale | BJ8: Placeholder values
A9: Manufactured home subdivision | B9: Housing | C9: For-Sale | D9: lot / home | E9: Y | F9: MH | G9: 4 | H9: 0 | I9: 0 | J9: 0 | K9: Y | L9: 0 | M9: 0 | N9: 0.05 | O9: 0 | P9: 3 | Q9: 0 | R9: 3 | S9: 3 | T9: N | U9: N | V9: 1 | W9: 1 | X9: 1 | Y9: 300 | Z9: Y | AA9: 1 | AB9: Y | AC9: 50 | AD9: 0 | AE9: 25000 | AF9: 116500 | AG9: 0 | AH9: 12 | AI9: 55000 | AJ9: 245000 | AK9: 0 | AL9: 0 | AM9: 0 | AN9: 0 | AO9: 0 | AP9: 0 | AQ9: 0 | AR9: 0.07 | AS9: 0 | AT9: 0 | AU9: 0.15 | AV9: 1 | AW9: 1 | AX9: 0 | AY9: 60 | AZ9: N | BA9: Y | BB9: 0 | BC9: 0 | BD9: 0 | BE9: N | BF9: 0 | BG9: 0 | BH9: N | BI9: No deed restriction against MH; MH-friendly zoning or unzoned county | BJ9: Vertical = Ridge Stone dealer cost ~$94K + set-up/foundation/skirting + flatwork (user-stated home cost; rest placeholder)
A10: Townhomes | B10: Housing | C10: For-Sale | D10: unit | E10: Y | F10: RES-ATT | G10: 10 | H10: 0 | I10: 0 | J10: 0 | K10: N | L10: 0 | M10: 0 | N10: 0.05 | O10: 0 | P10: 3 | Q10: 0 | R10: 4 | S10: 6 | T10: Y | U10: Y | V10: 1 | W10: 0 | X10: 0 | Y10: 300 | Z10: Y | AA10: 1 | AB10: Y | AC10: 25 | AD10: 0 | AE10: 25000 | AF10: 200000 | AG10: 0 | AH10: 12 | AI10: 45000 | AJ10: 300000 | AK10: 0 | AL10: 0 | AM10: 0 | AN10: 0 | AO10: 0 | AP10: 0 | AQ10: 0 | AR10: 0.07 | AS10: 0 | AT10: 0 | AU10: 0.15 | AV10: 1 | AW10: 1 | AX10: 0 | AY10: 60 | AZ10: N | BA10: Y | BB10: 0 | BC10: 0 | BD10: 0 | BE10: N | BF10: 0 | BG10: 0 | BH10: N | BI10: City water/sewer; zoning allows attached SF; near retail | BJ10: Placeholder values
A11: Ranchette subdivision (new internal road) | B11: Housing | C11: For-Sale | D11: lot | E11: Y | F11: RES-SF | G11: 0 | H11: 0 | I11: 5 | J11: 0 | K11: Y | L11: 0 | M11: 0 | N11: 0.05 | O11: 0 | P11: 3 | Q11: 0 | R11: 3 | S11: 1 | T11: N | U11: N | V11: 1 | W11: 1 | X11: 1 | Y11: 300 | Z11: Y | AA11: 0.15 | AB11: N | AC11: 150 | AD11: 0 | AE11: 15000 | AF11: 0 | AG11: 0 | AH11: 12 | AI11: 15000 | AJ11: 0 | AK11: 0 | AL11: 0 | AM11: 0 | AN11: 0 | AO11: 0 | AP11: 0 | AQ11: 0 | AR11: 0.07 | AS11: 15000 | AT11: 0 | AU11: 0.15 | AV11: 1 | AW11: 0 | AX11: 0 | AY11: 60 | AZ11: N | BA11: Y | BB11: 0 | BC11: 0 | BD11: 0 | BE11: N | BF11: 0 | BG11: 0 | BH11: N | BI11: Rural; low flood exposure; county allows 5+ ac lots without full subdivision improvements | BJ11: Revenue = lot premium + $/gross acre. Disturbance limited to road and pads
A12: Frontage split lots (no new road) | B12: Housing | C12: For-Sale | D12: lot | E12: Y | F12: RES-SF | G12: 0 | H12: 0 | I12: 2 | J12: 150 | K12: Y | L12: 0 | M12: 0 | N12: 0.05 | O12: 0 | P12: 3 | Q12: 0 | R12: 3 | S12: 1 | T12: N | U12: N | V12: 1 | W12: 1 | X12: 1 | Y12: 300 | Z12: Y | AA12: 0.02 | AB12: N | AC12: 0 | AD12: 0 | AE12: 5000 | AF12: 0 | AG12: 0 | AH12: 12 | AI12: 10000 | AJ12: 0 | AK12: 0 | AL12: 0 | AM12: 0 | AN12: 0 | AO12: 0 | AP12: 0 | AQ12: 0 | AR12: 0.07 | AS12: 15000 | AT12: 0 | AU12: 0.15 | AV12: 1 | AW12: 0 | AX12: 0 | AY12: 60 | AZ12: N | BA12: Y | BB12: 0 | BC12: 0 | BD12: 0 | BE12: N | BF12: 0 | BG12: 0 | BH12: Y | BI12: Existing public road frontage; county minimum lot size and frontage per lot | BJ12: Classic split-and-sell. Lots limited by frontage and min lot size; no internal road or detention
A13: Garage / car condos | B13: Storage | C13: For-Sale | D13: condo | E13: Y | F13: COM | G13: 0 | H13: 2900 | I13: 0 | J13: 0 | K13: N | L13: 0 | M13: 0 | N13: 0.05 | O13: 0.004 | P13: 10 | Q13: 0.3 | R13: 4 | S13: 4 | T13: N | U13: N | V13: 0.1 | W13: 0.1 | X13: 0.1 | Y13: 10 | Z13: Y | AA13: 1 | AB13: Y | AC13: 8 | AD13: 900 | AE13: 25000 | AF13: 85000 | AG13: 0 | AH13: 12 | AI13: 0 | AJ13: 135000 | AK13: 0 | AL13: 0 | AM13: 0 | AN13: 0 | AO13: 0 | AP13: 0 | AQ13: 0 | AR13: 0.07 | AS13: 0 | AT13: 0 | AU13: 0.15 | AV13: 0 | AW13: 1 | AX13: 0 | AY13: 100 | AZ13: N | BA13: Y | BB13: 0 | BC13: 0 | BD13: 0 | BE13: N | BF13: 0 | BG13: 0 | BH13: N | BI13: Affluent submarket; near lakes/airports; visible frontage | BJ13: Placeholder values
A14: Contractor shop condos | B14: Business & Trades | C14: For-Sale | D14: condo (2,000 SF) | E14: Y | F14: IND | G14: 0 | H14: 5700 | I14: 0 | J14: 0 | K14: N | L14: 0 | M14: 6 | N14: 0.05 | O14: 0.002 | P14: 10 | Q14: 0.3 | R14: 2 | S14: 4 | T14: N | U14: N | V14: 0.2 | W14: 0.2 | X14: 0.2 | Y14: 20 | Z14: Y | AA14: 1 | AB14: Y | AC14: 10 | AD14: 2500 | AE14: 25000 | AF14: 190000 | AG14: 0 | AH14: 12 | AI14: 0 | AJ14: 280000 | AK14: 0 | AL14: 0 | AM14: 0 | AN14: 0 | AO14: 0 | AP14: 0 | AQ14: 0 | AR14: 0.07 | AS14: 0 | AT14: 0 | AU14: 0.15 | AV14: 0 | AW14: 1 | AX14: 0 | AY14: 150 | AZ14: N | BA14: Y | BB14: 0 | BC14: 0 | BD14: 0 | BE14: N | BF14: 0 | BG14: 0 | BH14: N | BI14: Arterial access; trades demand; light industrial / commercial zoning or unzoned county | BJ14: Placeholder values
A15: Professional office condos | B15: Business & Trades | C15: For-Sale | D15: condo (1,500 SF) | E15: Y | F15: OFF | G15: 0 | H15: 6000 | I15: 0 | J15: 0 | K15: N | L15: 0 | M15: 4 | N15: 0.05 | O15: 0.002 | P15: 10 | Q15: 0.25 | R15: 1.5 | S15: 4 | T15: N | U15: Y | V15: 0.25 | W15: 0.25 | X15: 0.25 | Y15: 30 | Z15: Y | AA15: 1 | AB15: Y | AC15: 8 | AD15: 3000 | AE15: 25000 | AF15: 300000 | AG15: 0 | AH15: 12 | AI15: 0 | AJ15: 450000 | AK15: 0 | AL15: 0 | AM15: 0 | AN15: 0 | AO15: 0 | AP15: 0 | AQ15: 0 | AR15: 0.07 | AS15: 0 | AT15: 0 | AU15: 0.15 | AV15: 0 | AW15: 1 | AX15: 0 | AY15: 150 | AZ15: N | BA15: Y | BB15: 0 | BC15: 0 | BD15: 0 | BE15: N | BF15: 0 | BG15: 0 | BH15: N | BI15: Near rooftops and medical/retail; commercial zoning | BJ15: Placeholder values
A16: Manufactured home community (MHC) | B16: Housing | C16: Income | D16: pad | E16: Y | F16: MH | G16: 7 | H16: 0 | I16: 0 | J16: 0 | K16: N | L16: 5 | M16: 0 | N16: 0.05 | O16: 0 | P16: 3 | Q16: 0 | R16: 3 | S16: 0 | T16: N | U16: N | V16: 1 | W16: 0.25 | X16: 0 | Y16: 250 | Z16: Y | AA16: 1 | AB16: Y | AC16: 40 | AD16: 0 | AE16: 40000 | AF16: 12000 | AG16: 0 | AH16: 12 | AI16: 0 | AJ16: 0 | AK16: 6600 | AL16: 0.05 | AM16: 0.07 | AN16: 1200 | AO16: 0.05 | AP16: 0.15 | AQ16: 24 | AR16: 0.065 | AS16: 40000 | AT16: 0 | AU16: 0.15 | AV16: 1 | AW16: 1 | AX16: 1 | AY16: 60 | AZ16: N | BA16: Y | BB16: 0 | BC16: 0 | BD16: 0 | BE16: N | BF16: 0 | BG16: 0 | BH16: N | BI16: MHC zoning or unzoned county; sewer or package plant for density; workforce job growth | BJ16: Pad-only model. Rental community: septic limited by gallons/day per acre, not the subdivided-lot rule
... A66: Cell tower ground lease | B66: Infrastructure | C66: Land Play | D66: acre | E66: N | F66: UTIL | G66: 0 | H66: 43560 | I66: 0 | J66: 0 | K66: N | L66: 0 | M66: 0.25 | N66: 0.05 | O66: 0 | P66: 3 | Q66: 0 | R66: 0 | S66: 0 | T66: N | U66: N | V66: 0 | W66: 0 | X66: 0 | Y66: 0 | Z66: N | AA66: 1 | AB66: Y | AC66: 0 | AD66: 0 | AE66: 0 | AF66: 0 | AG66: 0 | AH66: 12 | AI66: 0 | AJ66: 0 | AK66: 0 | AL66: 0 | AM66: 0 | AN66: 0 | AO66: 0 | AP66: 0 | AQ66: 0 | AR66: 0.065 | AS66: 0 | AT66: 6000 | AU66: 0.25 | AV66: 0 | AW66: 0 | AX66: 1 | AY66: 100 | AZ66: N | BA66: N | BB66: 0 | BC66: 0 | BD66: 0 | BE66: N | BF66: 0 | BG66: 0 | BH66: N | BI66: Carrier coverage gap; jurisdiction allows towers; height/FAA clearance | BJ66: Stackable with other uses on the same parcel; carrier pays entitlement. Rent per acre = $1,500/yr on 0.25 ac

Sheet Use_Effective
A1: Use Effective - the inputs the engine actually uses for this parcel and org
A2: Cost-type fields: Org > Market > Default x index. Revenue-type fields: Market (City > County > State) > Org > Default x index. Do not edit.
