Workbook

Sheet ReadMe
A1: Landova Proforma v2
A2: Every Landova use, one engine. Parcel facts + use defaults + cost library -> what fits -> cost -> three exits -> max offer.
A4: Start here
A5: 1. Parcel | B5: Enter or paste the parcel's facts and the asking price.
A6: 2. Best_Use | B6: Every use ranked by the most you could pay for this land. This is the 'land value today to its best use' screen.
A7: 3. Deal_View | B7: Pick one use and read its numbers top to bottom: yield, quantities, budget, income, exits, max offer.
A9: How it is built
A10: Four engines | B10: For-Sale (lots, homes, condos) · Income (anything 5+ units or commercial: valued on NOI and cap rate) · Operator Pad (Landova delivers a pad, an operator runs the business) · Land Play (leases and entitle-and-sell).
A11: Three exits for every use | B11: 1) Land / pad sale 2) Build & sell 3) Build & hold / lease. Use_Library says which are allowed.
A12: Use_Library | B12: One row per use: how it is sized, what it costs, what it earns, and where it works. Add a use = add a row.
A13: Engine | B13: One row per use, one column per step. This tab is the spec Ryan codes from - every column header is a calculation step.
A14: Max offer | B14: The engine solves for the land price that leaves exactly the required margin. Costs that rise with land price (closing, carry, financing, property tax) are included, so the answer is exact.
A15: Market cap | B15: Max usable acres stops the model from pretending 20 acres can all be QSR pads. Leftover acres are resold at the raw land value.
A17: Color code
A18: Blue on yellow | B18: Input - edit
A19: Black | B19: Formula - don't edit
A20: Green | B20: Link to another tab
A22: Before using on a live deal
A23: Placeholders | B23: Every cost, price, rent, cap rate, county factor and land value is a placeholder chosen to show the mechanics. Replace with real comps, bids and your actuals.
A24: Location tests | B24: Traffic, households, highway distance, corner and substation minimums in Use_Library are enforced: a use that fails gets no capacity and drops to the bottom. The written location notes are NOT enforced - the land search must apply them.
A25: Not in this workbook | B25: Monthly cash flow / IRR, multifamily unit mix and LP/GP waterfall, operating-business P&Ls. See the build guide.

Sheet Parcel
A1: Parcel Inputs
A2: One parcel. In the software these fill from Landova's site analysis. Blue on yellow = input.
B4: Input | C4: Value | D4: Unit | E4: Source in Landova
B5: Parcel name | C5: Sample Parcel - Grayson County | E5: User
B6: County | C6: Grayson | E6: Parcel record
B7: Cost scenario | C7: Base | D7: Low/Base/High | E7: User
B8: Gross acres | C8: 20 | D8: ac | E8: Parcel boundary
B9: Buildable % | C9: 0.78 | D9: % of gross | E9: Buildable-land analysis
B10: Average slope | C10: 0.04 | D10: % | E10: Topography
B11: Tree cover | C11: 0.35 | D11: % | E11: 3D tree coverage
B12: Road frontage | C12: 660 | D12: LF | E12: Frontage analysis
B13: Public water at site | C13: Y | D13: Y/N | E13: Utilities layer
B14: Distance to water main | C14: 0 | D14: LF | E14: Utilities layer
B15: Public sewer at site | C15: N | D15: Y/N | E15: Utilities layer
B16: Distance to sewer main | C16: 6000 | D16: LF | E16: Utilities layer
B17: Septic soil rating | C17: Fair | D17: Good/Fair/Poor | E17: Soil composition
B18: Asking / offer price (whole parcel) | C18: 300000 | D18: $ | E18: Listing or user
B19: Traffic count on frontage road | C19: 4000 | D19: vehicles/day | E19: TxDOT counts
B20: Households within 3 miles | C20: 2500 | D20: households | E20: Census / growth layer
B21: Miles to nearest highway interchange | C21: 6 | D21: miles | E21: Road network
B22: Corner lot (hard corner on two roads) | C22: N | D22: Y/N | E22: Frontage analysis
B23: Miles to substation with capacity | C23: 3 | D23: miles | E23: Utility / transmission layer
B25: Derived (formulas)
B26: Net buildable acres | C26: =Parcel!$C$8*Parcel!$C$9 -> 15.6
B27: Public water used (1 = yes) | C27: =IF(OR(Parcel!$C$13="Y",Parcel!$C$14<=Assumptions!$C$5),1,0) -> 1
B28: Public sewer used (1 = yes) | C28: =IF(OR(Parcel!$C$15="Y",Parcel!$C$16<=Assumptions!$C$6),1,0) -> 0
B29: Off-site water extension LF | C29: =IF(Parcel!$C$13="Y",0,Parcel!$C$14)*Parcel!$C$27 -> 0
B30: Off-site sewer extension LF | C30: =IF(Parcel!$C$15="Y",0,Parcel!$C$16)*Parcel!$C$28 -> 0
B31: Scenario column | C31: =MATCH(Parcel!$C$7,Lookups!$J$5:$J$7,0) -> 2
B32: Regional cost factor | C32: =IFERROR(INDEX(Lookups!$B$5:$B$10,MATCH(Parcel!$C$6,Lookups!$A$5:$A$10,0)),1) -> 1
B33: Grading multiplier (slope) | C33: =INDEX(Lookups!$H$5:$H$7,MATCH(TRUE(),INDEX(Parcel!$C$10<=Lookups!$G$5:$G$7,0),0)) -> 1
B34: Septic multiplier (soil) | C34: =IFERROR(INDEX(Lookups!$E$5:$E$7,MATCH(Parcel!$C$17,Lookups!$D$5:$D$7,0)),1) -> 1.2

Sheet Best_Use
A1: Best Use - what this parcel is worth to each use
A2: Every use in the library run against the parcel on the Parcel tab, ranked by max offer. This is the 'land value today to its best use' screen.
B3: Parcel: | C3: =Parcel!$C$5 -> Sample Parcel - Grayson County | E3: Asking: | F3: =Parcel!$C$18 -> 300000
A5: Rank | B5: Use | C5: Engine | D5: Capacity | E5: Unit | F5: Best exit | G5: Max offer | H5: Opening offer | I5: Max - asking | J5: Max / gross ac | K5: Max / unit | L5: Binding constraint | M5: Flags | N5: row
A6: 1 | B6: =INDEX(Engine!$A$6:$A$58,$N6) -> Boat & RV storage | C6: =INDEX(Engine!$B$6:$B$58,$N6) -> Income | D6: =INDEX(Engine!$S$6:$S$58,$N6) -> 373 | E6: =INDEX(Engine!$C$6:$C$58,$N6) -> stall | F6: =INDEX(Engine!$CW$6:$CW$58,$N6) -> Build & hold / lease | G6: =INDEX(Engine!$CV$6:$CV$58,$N6) -> 1485094.8 | H6: =INDEX(Engine!$CX$6:$CX$58,$N6) -> 1262330.6 | I6: =INDEX(Engine!$CY$6:$CY$58,$N6) -> 1185094.8 | J6: =INDEX(Engine!$CZ$6:$CZ$58,$N6) -> 74254.742 | K6: =INDEX(Engine!$DA$6:$DA$58,$N6) -> 3981.4875 | L6: =INDEX(Engine!$T$6:$T$58,$N6) -> Site area / parking | M6: =INDEX(Engine!$DB$6:$DB$58,$N6) -> Only 6 ac used - rest resold. | N6: =MATCH(LARGE(Engine!$DC$6:$DC$58,A6),Engine!$DC$6:$DC$58,0) -> 48
A7: 2 | B7: =INDEX(Engine!$A$6:$A$58,$N7) -> Workforce / extended-stay RV park | C7: =INDEX(Engine!$B$6:$B$58,$N7) -> Income | D7: =INDEX(Engine!$S$6:$S$58,$N7) -> 234 | E7: =INDEX(Engine!$C$6:$C$58,$N7) -> site | F7: =INDEX(Engine!$CW$6:$CW$58,$N7) -> Build & hold / lease | G7: =INDEX(Engine!$CV$6:$CV$58,$N7) -> 660770.35 | H7: =INDEX(Engine!$CX$6:$CX$58,$N7) -> 561654.8 | I7: =INDEX(Engine!$CY$6:$CY$58,$N7) -> 360770.35 | J7: =INDEX(Engine!$CZ$6:$CZ$58,$N7) -> 33038.518 | K7: =INDEX(Engine!$DA$6:$DA$58,$N7) -> 2823.8049 | L7: =INDEX(Engine!$T$6:$T$58,$N7) -> Density | M7: =INDEX(Engine!$DB$6:$DB$58,$N7) | N7: =MATCH(LARGE(Engine!$DC$6:$DC$58,A7),Engine!$DC$6:$DC$58,0) -> 12
A8: 3 | B8: =INDEX(Engine!$A$6:$A$58,$N8) -> Supplier build-to-suit near major plants | C8: =INDEX(Engine!$B$6:$B$58,$N8) -> Income | D8: =INDEX(Engine!$S$6:$S$58,$N8) -> 239196.67 | E8: =INDEX(Engine!$C$6:$C$58,$N8) -> bldg SF | F8: =INDEX(Engine!$CW$6:$CW$58,$N8) -> Land / pad sale | G8: =INDEX(Engine!$CV$6:$CV$58,$N8) -> 493980.85 | H8: =INDEX(Engine!$CX$6:$CX$58,$N8) -> 419883.72 | I8: =INDEX(Engine!$CY$6:$CY$58,$N8) -> 193980.85 | J8: =INDEX(Engine!$CZ$6:$CZ$58,$N8) -> 24699.042 | K8: =INDEX(Engine!$DA$6:$DA$58,$N8) -> 2.065166 | L8: =INDEX(Engine!$T$6:$T$58,$N8) -> Site area / parking | M8: =INDEX(Engine!$DB$6:$DB$58,$N8) | N8: =MATCH(LARGE(Engine!$DC$6:$DC$58,A8),Engine!$DC$6:$DC$58,0) -> 41
A9: 4 | B9: =INDEX(Engine!$A$6:$A$58,$N9) -> Homesites (stick-built, for sale) | C9: =INDEX(Engine!$B$6:$B$58,$N9) -> For-Sale | D9: =INDEX(Engine!$S$6:$S$58,$N9) -> 24 | E9: =INDEX(Engine!$C$6:$C$58,$N9) -> lot / home | F9: =INDEX(Engine!$CW$6:$CW$58,$N9) -> Land / pad sale | G9: =INDEX(Engine!$CV$6:$CV$58,$N9) -> 441967.92 | H9: =INDEX(Engine!$CX$6:$CX$58,$N9) -> 375672.73 | I9: =INDEX(Engine!$CY$6:$CY$58,$N9) -> 141967.92 | J9: =INDEX(Engine!$CZ$6:$CZ$58,$N9) -> 22098.396 | K9: =INDEX(Engine!$DA$6:$DA$58,$N9) -> 18415.33 | L9: =INDEX(Engine!$T$6:$T$58,$N9) -> Septic lot size | M9: =INDEX(Engine!$DB$6:$DB$58,$N9) | N9: =MATCH(LARGE(Engine!$DC$6:$DC$58,A9),Engine!$DC$6:$DC$58,0) -> 1
A10: 5 | B10: =INDEX(Engine!$A$6:$A$58,$N10) -> Finished / entitled lots | C10: =INDEX(Engine!$B$6:$B$58,$N10) -> For-Sale | D10: =INDEX(Engine!$S$6:$S$58,$N10) -> 24 | E10: =INDEX(Engine!$C$6:$C$58,$N10) -> lot | F10: =INDEX(Engine!$CW$6:$CW$58,$N10) -> Land / pad sale | G10: =INDEX(Engine!$CV$6:$CV$58,$N10) -> 351753.61 | H10: =INDEX(Engine!$CX$6:$CX$58,$N10) -> 298990.57 | I10: =INDEX(Engine!$CY$6:$CY$58,$N10) -> 51753.61 | J10: =INDEX(Engine!$CZ$6:$CZ$58,$N10) -> 17587.68 | K10: =INDEX(Engine!$DA$6:$DA$58,$N10) -> 14656.4 | L10: =INDEX(Engine!$T$6:$T$58,$N10) -> Septic lot size | M10: =INDEX(Engine!$DB$6:$DB$58,$N10) | N10: =MATCH(LARGE(Engine!$DC$6:$DC$58,A10),Engine!$DC$6:$DC$58,0) -> 2
A11: 6 | B11: =INDEX(Engine!$A$6:$A$58,$N11) -> Manufactured home subdivision | C11: =INDEX(Engine!$B$6:$B$58,$N11) -> For-Sale | D11: =INDEX(Engine!$S$6:$S$58,$N11) -> 24 | E11: =INDEX(Engine!$C$6:$C$58,$N11) -> lot / home | F11: =INDEX(Engine!$CW$6:$CW$58,$N11) -> Build & sell | G11: =INDEX(Engine!$CV$6:$CV$58,$N11) -> 303520.56 | H11: =INDEX(Engine!$CX$6:$CX$58,$N11) -> 257992.48 | I11: =INDEX(Engine!$CY$6:$CY$58,$N11) -> 3520.5642 | J11: =INDEX(Engine!$CZ$6:$CZ$58,$N11) -> 15176.028 | K11: =INDEX(Engine!$DA$6:$DA$58,$N11) -> 12646.69 | L11: =INDEX(Engine!$T$6:$T$58,$N11) -> Septic lot size | M11: =INDEX(Engine!$DB$6:$DB$58,$N11) | N11: =MATCH(LARGE(Engine!$DC$6:$DC$58,A11),Engine!$DC$6:$DC$58,0) -> 5
A12: 7 | B12: =INDEX(Engine!$A$6:$A$58,$N12) -> Active-adult 55+ (for sale) | C12: =INDEX(Engine!$B$6:$B$58,$N12) -> For-Sale | D12: =INDEX(Engine!$S$6:$S$58,$N12) -> 24 | E12: =INDEX(Engine!$C$6:$C$58,$N12) -> lot / home | F12: =INDEX(Engine!$CW$6:$CW$58,$N12) -> Land / pad sale | G12: =INDEX(Engine!$CV$6:$CV$58,$N12) -> 289960.35 | H12: =INDEX(Engine!$CX$6:$CX$58,$N12) -> 246466.3 | I12: =INDEX(Engine!$CY$6:$CY$58,$N12) -> -10039.649 | J12: =INDEX(Engine!$CZ$6:$CZ$58,$N12) -> 14498.018 | K12: =INDEX(Engine!$DA$6:$DA$58,$N12) -> 12081.681 | L12: =INDEX(Engine!$T$6:$T$58,$N12) -> Septic lot size | M12: =INDEX(Engine!$DB$6:$DB$58,$N12) | N12: =MATCH(LARGE(Engine!$DC$6:$DC$58,A12),Engine!$DC$6:$DC$58,0) -> 3
A13: 8 | B13: =INDEX(Engine!$A$6:$A$58,$N13) -> Event venue / wedding barn | C13: =INDEX(Engine!$B$6:$B$58,$N13) -> Operator Pad | D13: =INDEX(Engine!$S$6:$S$58,$N13) -> 14.196 | E13: =INDEX(Engine!$C$6:$C$58,$N13) -> acre | F13: =INDEX(Engine!$CW$6:$CW$58,$N13) -> Land / pad sale | G13: =INDEX(Engine!$CV$6:$CV$58,$N13) -> 200241.01 | H13: =INDEX(Engine!$CX$6:$CX$58,$N13) -> 170204.86 | I13: =INDEX(Engine!$CY$6:$CY$58,$N13) -> -99758.993 | J13: =INDEX(Engine!$CZ$6:$CZ$58,$N13) -> 10012.05 | K13: =INDEX(Engine!$DA$6:$DA$58,$N13) -> 14105.453 | L13: =INDEX(Engine!$T$6:$T$58,$N13) -> Site area / parking | M13: =INDEX(Engine!$DB$6:$DB$58,$N13) | N13: =MATCH(LARGE(Engine!$DC$6:$DC$58,A13),Engine!$DC$6:$DC$58,0) -> 38
A14: 9 | B14: =INDEX(Engine!$A$6:$A$58,$N14) -> Entry-level for-sale homes | C14: =INDEX(Engine!$B$6:$B$58,$N14) -> For-Sale | D14: =INDEX(Engine!$S$6:$S$58,$N14) -> 24 | E14: =INDEX(Engine!$C$6:$C$58,$N14) -> lot / home | F14: =INDEX(Engine!$CW$6:$CW$58,$N14) -> Land / pad sale | G14: =INDEX(Engine!$CV$6:$CV$58,$N14) -> 199746.04 | H14: =INDEX(Engine!$CX$6:$CX$58,$N14) -> 169784.13 | I14: =INDEX(Engine!$CY$6:$CY$58,$N14) -> -100253.96 | J14: =INDEX(Engine!$CZ$6:$CZ$58,$N14) -> 9987.302 | K14: =INDEX(Engine!$DA$6:$DA$58,$N14) -> 8322.7517 | L14: =INDEX(Engine!$T$6:$T$58,$N14) -> Septic lot size | M14: =INDEX(Engine!$DB$6:$DB$58,$N14) | N14: =MATCH(LARGE(Engine!$DC$6:$DC$58,A14),Engine!$DC$6:$DC$58,0) -> 4
A15: 10 | B15: =INDEX(Engine!$A$6:$A$58,$N15) -> Private water / wastewater (package plant) site | C15: =INDEX(Engine!$B$6:$B$58,$N15) -> Land Play | D15: =INDEX(Engine!$S$6:$S$58,$N15) -> 5 | E15: =INDEX(Engine!$C$6:$C$58,$N15) -> acre | F15: =INDEX(Engine!$CW$6:$CW$58,$N15) -> Land / pad sale | G15: =INDEX(Engine!$CV$6:$CV$58,$N15) -> 116965.95 | H15: =INDEX(Engine!$CX$6:$CX$58,$N15) -> 99421.059 | I15: =INDEX(Engine!$CY$6:$CY$58,$N15) -> -183034.05 | J15: =INDEX(Engine!$CZ$6:$CZ$58,$N15) -> 5848.2976 | K15: =INDEX(Engine!$DA$6:$DA$58,$N15) -> 23393.19 | L15: =INDEX(Engine!$T$6:$T$58,$N15) -> Site area / parking | M15: =INDEX(Engine!$DB$6:$DB$58,$N15) -> Only 5 ac used - rest resold. | N15: =MATCH(LARGE(Engine!$DC$6:$DC$58,A15),Engine!$DC$6:$DC$58,0) -> 51
A16: 11 | B16: =INDEX(Engine!$A$6:$A$58,$N16) -> Powered land for data centers | C16: =INDEX(Engine!$B$6:$B$58,$N16) -> Land Play | D16: =INDEX(Engine!$S$6:$S$58,$N16) -> 0 | E16: =INDEX(Engine!$C$6:$C$58,$N16) -> acre | F16: =INDEX(Engine!$CW$6:$CW$58,$N16) -> None works | G16: =INDEX(Engine!$CV$6:$CV$58,$N16) -> 0 | H16: =INDEX(Engine!$CX$6:$CX$58,$N16) -> 0 | I16: =INDEX(Engine!$CY$6:$CY$58,$N16) -> -300000 | J16: =INDEX(Engine!$CZ$6:$CZ$58,$N16) -> 0 | K16: =INDEX(Engine!$DA$6:$DA$58,$N16) -> 0 | L16: =INDEX(Engine!$T$6:$T$58,$N16) -> Location fails | M16: =INDEX(Engine!$DB$6:$DB$58,$N16) -> Over 1 mi to substation. | N16: =MATCH(LARGE(Engine!$DC$6:$DC$58,A16),Engine!$DC$6:$DC$58,0) -> 53
A17: 12 | B17: =INDEX(Engine!$A$6:$A$58,$N17) -> Battery storage / solar land lease | C17: =INDEX(Engine!$B$6:$B$58,$N17) -> Land Play | D17: =INDEX(Engine!$S$6:$S$58,$N17) -> 0 | E17: =INDEX(Engine!$C$6:$C$58,$N17) -> acre | F17: =INDEX(Engine!$CW$6:$CW$58,$N17) -> None works | G17: =INDEX(Engine!$CV$6:$CV$58,$N17) -> 0 | H17: =INDEX(Engine!$CX$6:$CX$58,$N17) -> 0 | I17: =INDEX(Engine!$CY$6:$CY$58,$N17) -> -300000 | J17: =INDEX(Engine!$CZ$6:$CZ$58,$N17) -> 0 | K17: =INDEX(Engine!$DA$6:$DA$58,$N17) -> 0 | L17: =INDEX(Engine!$T$6:$T$58,$N17) -> Location fails | M17: =INDEX(Engine!$DB$6:$DB$58,$N17) -> Over 2 mi to substation. | N17: =MATCH(LARGE(Engine!$DC$6:$DC$58,A17),Engine!$DC$6:$DC$58,0) -> 52
... A58: 53 | B58: =INDEX(Engine!$A$6:$A$58,$N58) -> Townhomes | C58: =INDEX(Engine!$B$6:$B$58,$N58) -> For-Sale | D58: =INDEX(Engine!$S$6:$S$58,$N58) -> 0 | E58: =INDEX(Engine!$C$6:$C$58,$N58) -> unit | F58: =INDEX(Engine!$CW$6:$CW$58,$N58) -> None works | G58: =INDEX(Engine!$CV$6:$CV$58,$N58) -> 0 | H58: =INDEX(Engine!$CX$6:$CX$58,$N58) -> 0 | I58: =INDEX(Engine!$CY$6:$CY$58,$N58) -> -300000 | J58: =INDEX(Engine!$CZ$6:$CZ$58,$N58) -> 0 | K58: =INDEX(Engine!$DA$6:$DA$58,$N58) -> 0 | L58: =INDEX(Engine!$T$6:$T$58,$N58) -> Needs public sewer | M58: =INDEX(Engine!$DB$6:$DB$58,$N58) -> Nothing fits. | N58: =MATCH(LARGE(Engine!$DC$6:$DC$58,A58),Engine!$DC$6:$DC$58,0) -> 6
B60: Read with care: every number is a placeholder, and a high max offer means only that the math works. Check the location requirements (Use_Library) before believing any row.

Sheet Deal_View
A1: Deal View - one use in detail
A2: Pick a use. Everything below is read from the Engine row for that use, top to bottom, so you can audit each step.
B4: Use | C4: Multifamily - large garden (150+ units)
B5: Engine row | C5: =MATCH(C4,Engine!$A$6:$A$58,0) -> 14
B6: Location requirements | C6: =INDEX(Use_Library!$AS$5:$AS$57,$C$5) -> MF zoning; arterial frontage; employment within 20 min; sewer capacity letter
B9: Identity
B10: Engine | C10: =INDEX(Engine!$B$6:$B$58,$C$5) -> Income
B11: Capacity unit | C11: =INDEX(Engine!$C$6:$C$58,$C$5) -> unit
B13: Yield
B14: Usable acres (net - open space - detention) | C14: =INDEX(Engine!$D$6:$D$58,$C$5) -> 14.196
B15: Usable acres used by this use (market cap) | C15: =INDEX(Engine!$E$6:$E$58,$C$5) -> 14.196
B16: Share of parcel used | C16: =INDEX(Engine!$F$6:$F$58,$C$5) -> 1
B17: Net acres in use | C17: =INDEX(Engine!$G$6:$G$58,$C$5) -> 15.6
B18: Detention acres | C18: =INDEX(Engine!$H$6:$H$58,$C$5) -> 0.624
B19: Developed acres | C19: =INDEX(Engine!$I$6:$I$58,$C$5) -> 14.82
B20: Excess gross acres (resold as raw land) | C20: =INDEX(Engine!$J$6:$J$58,$C$5) -> 0
B21: Sewer requirement met (1/0) | C21: =INDEX(Engine!$K$6:$K$58,$C$5) -> 0
B22: Water requirement met (1/0) | C22: =INDEX(Engine!$L$6:$L$58,$C$5) -> 1
B23: Location test failures | C23: =INDEX(Engine!$M$6:$M$58,$C$5) -> Under 8,000 households in 3 mi.
B24: Location passes (1/0) | C24: =INDEX(Engine!$N$6:$N$58,$C$5) -> 0
B25: Parcel big enough (1/0) | C25: =INDEX(Engine!$O$6:$O$58,$C$5) -> 1
B26: Capacity by density | C26: =INDEX(Engine!$P$6:$P$58,$C$5) -> 374.4
B27: Capacity by site area | C27: =INDEX(Engine!$Q$6:$Q$58,$C$5) -> 515.3148
B28: Capacity by septic lot size | C28: =INDEX(Engine!$R$6:$R$58,$C$5) -> 1000000000
B29: CAPACITY (units / SF / acres) | C29: =INDEX(Engine!$S$6:$S$58,$C$5) -> 0
B30: Binding constraint | C30: =INDEX(Engine!$T$6:$T$58,$C$5) -> Location fails
B31: Anything fits (1/0) | C31: =INDEX(Engine!$U$6:$U$58,$C$5) -> 0
B32: Horizontal by us (1/0) | C32: =INDEX(Engine!$V$6:$V$58,$C$5) -> 0
B34: Quantities
B35: Internal road LF | C35: =INDEX(Engine!$W$6:$W$58,$C$5) -> 0
B36: Paving / hardscape SF | C36: =INDEX(Engine!$X$6:$X$58,$C$5) -> 0
B37: Water line LF | C37: =INDEX(Engine!$Y$6:$Y$58,$C$5) -> 0
B38: Water taps | C38: =INDEX(Engine!$Z$6:$Z$58,$C$5) -> 0
B39: Sewer line LF | C39: =INDEX(Engine!$AA$6:$AA$58,$C$5) -> 0
B40: Sewer taps | C40: =INDEX(Engine!$AB$6:$AB$58,$C$5) -> 0
B41: Septic systems | C41: =INDEX(Engine!$AC$6:$AC$58,$C$5) -> 0
B42: Private wells | C42: =INDEX(Engine!$AD$6:$AD$58,$C$5) -> 0
B43: Acres to clear | C43: =INDEX(Engine!$AE$6:$AE$58,$C$5) -> 0
B44: Acres to grade | C44: =INDEX(Engine!$AF$6:$AF$58,$C$5) -> 0
B45: Lots to plat | C45: =INDEX(Engine!$AG$6:$AG$58,$C$5) -> 0
...

Sheet Use_Library
A1: Use Library
A2: One row per use. Every economic value is a PLACEHOLDER for North Texas - replace with comps, bids and your own actuals. Add a use by adding a row (and extending the Engine tab).
A4: Use | B4: Category | C4: Engine | D4: Capacity unit | E4: Discrete units (Y/N) | F4: Max density (units / net ac; 0 = n/a) | G4: Site SF per unit (0 = n/a) | H4: Septic lot-size rule (Y/N) | I4: Requires public sewer (Y/N) | J4: Requires public water (Y/N) | K4: Horizontal work by us (Y/N) | L4: Min usable acres needed (0 = none) | M4: Max usable acres market supports (0 = no cap) | N4: Open space % of net | O4: Road / drive LF per unit | P4: Paving SF per unit | Q4: Utility taps per unit | R4: Septic systems per unit (if no sewer) | S4: Entitlement & zoning $ (fixed) | T4: Vertical cost per unit | U4: Lot sale price per unit (For-Sale) | V4: Finished sale price per unit (For-Sale) | W4: Rent per unit per year (Income) | X4: Other income % of rent | Y4: Stabilized vacancy | Z4: Opex per unit per year, excl. tax | AA4: Management % of EGI | AB4: Expense recovery % (NNN) | AC4: TI + leasing commissions per unit | AD4: Lease-up months | AE4: Exit / lease cap rate | AF4: Land / pad sale price per usable acre | AG4: Ground / land lease rent per acre per year | AH4: Development months | AI4: Required margin | AJ4: Exit allowed: Land / pad sale (1/0) | AK4: Exit allowed: Build & sell (1/0) | AL4: Exit allowed: Build & hold / lease (1/0) | AM4: Min road frontage LF | AN4: Min traffic count on frontage (VPD; 0 = none) | AO4: Min households within 3 mi (0 = none) | AP4: Max miles to highway interchange (0 = none) | AQ4: Corner lot required (Y/N) | AR4: Max miles to substation w/ capacity (0 = none) | AS4: Location requirements (land-search filters) | AT4: Notes
A5: Homesites (stick-built, for sale) | B5: Housing | C5: For-Sale | D5: lot / home | E5: Y | F5: 4 | G5: 0 | H5: Y | I5: N | J5: N | K5: Y | L5: 0 | M5: 0 | N5: 0.05 | O5: 50 | P5: 0 | Q5: 1 | R5: 1 | S5: 25000 | T5: 245000 | U5: 80000 | V5: 375000 | W5: 0 | X5: 0 | Y5: 0 | Z5: 0 | AA5: 0 | AB5: 0 | AC5: 0 | AD5: 0 | AE5: 0.07 | AF5: 0 | AG5: 0 | AH5: 12 | AI5: 0.15 | AJ5: 1 | AK5: 1 | AL5: 0 | AM5: 60 | AN5: 0 | AO5: 0 | AP5: 0 | AQ5: N | AR5: 0 | AS5: Within growth area; school district; < 30 min to job centers; no deed restriction on lot size | AT5: Placeholder values
A6: Finished / entitled lots | B6: Housing | C6: For-Sale | D6: lot | E6: Y | F6: 4 | G6: 0 | H6: Y | I6: N | J6: N | K6: Y | L6: 0 | M6: 0 | N6: 0.05 | O6: 50 | P6: 0 | Q6: 1 | R6: 1 | S6: 25000 | T6: 0 | U6: 75000 | V6: 0 | W6: 0 | X6: 0 | Y6: 0 | Z6: 0 | AA6: 0 | AB6: 0 | AC6: 0 | AD6: 0 | AE6: 0.07 | AF6: 0 | AG6: 0 | AH6: 12 | AI6: 0.15 | AJ6: 1 | AK6: 0 | AL6: 0 | AM6: 60 | AN6: 0 | AO6: 0 | AP6: 0 | AQ6: N | AR6: 0 | AS6: Builder demand in submarket; utilities within reach; platting allowed | AT6: Placeholder values
A7: Active-adult 55+ (for sale) | B7: Housing | C7: For-Sale | D7: lot / home | E7: Y | F7: 5 | G7: 0 | H7: Y | I7: N | J7: N | K7: Y | L7: 0 | M7: 0 | N7: 0.05 | O7: 45 | P7: 0 | Q7: 1 | R7: 1 | S7: 25000 | T7: 230000 | U7: 70000 | V7: 360000 | W7: 0 | X7: 0 | Y7: 0 | Z7: 0 | AA7: 0 | AB7: 0 | AC7: 0 | AD7: 0 | AE7: 0.07 | AF7: 0 | AG7: 0 | AH7: 12 | AI7: 0.15 | AJ7: 1 | AK7: 1 | AL7: 0 | AM7: 60 | AN7: 0 | AO7: 0 | AP7: 0 | AQ7: N | AR7: 0 | AS7: Near healthcare, retail and lakes/golf; 60+ population growth | AT7: Placeholder values
A8: Entry-level for-sale homes | B8: Housing | C8: For-Sale | D8: lot / home | E8: Y | F8: 5 | G8: 0 | H8: Y | I8: N | J8: N | K8: Y | L8: 0 | M8: 0 | N8: 0.05 | O8: 45 | P8: 0 | Q8: 1 | R8: 1 | S8: 25000 | T8: 210000 | U8: 65000 | V8: 310000 | W8: 0 | X8: 0 | Y8: 0 | Z8: 0 | AA8: 0 | AB8: 0 | AC8: 0 | AD8: 0 | AE8: 0.07 | AF8: 0 | AG8: 0 | AH8: 12 | AI8: 0.15 | AJ8: 1 | AK8: 1 | AL8: 0 | AM8: 60 | AN8: 0 | AO8: 0 | AP8: 0 | AQ8: N | AR8: 0 | AS8: Workforce demand (job growth); price-point gap vs. resale | AT8: Placeholder values
A9: Manufactured home subdivision | B9: Housing | C9: For-Sale | D9: lot / home | E9: Y | F9: 4 | G9: 0 | H9: Y | I9: N | J9: N | K9: Y | L9: 0 | M9: 0 | N9: 0.05 | O9: 50 | P9: 0 | Q9: 1 | R9: 1 | S9: 25000 | T9: 116500 | U9: 55000 | V9: 245000 | W9: 0 | X9: 0 | Y9: 0 | Z9: 0 | AA9: 0 | AB9: 0 | AC9: 0 | AD9: 0 | AE9: 0.07 | AF9: 0 | AG9: 0 | AH9: 12 | AI9: 0.15 | AJ9: 1 | AK9: 1 | AL9: 0 | AM9: 60 | AN9: 0 | AO9: 0 | AP9: 0 | AQ9: N | AR9: 0 | AS9: No deed restriction against MH; county (not city) jurisdiction or MH-friendly zoning | AT9: Vertical = Ridge Stone dealer cost ~$94K + set-up/foundation/skirting + flatwork (user-stated home cost; rest placeholder)
A10: Townhomes | B10: Housing | C10: For-Sale | D10: unit | E10: Y | F10: 10 | G10: 0 | H10: N | I10: Y | J10: Y | K10: Y | L10: 0 | M10: 0 | N10: 0.05 | O10: 25 | P10: 0 | Q10: 1 | R10: 0 | S10: 25000 | T10: 200000 | U10: 45000 | V10: 300000 | W10: 0 | X10: 0 | Y10: 0 | Z10: 0 | AA10: 0 | AB10: 0 | AC10: 0 | AD10: 0 | AE10: 0.07 | AF10: 0 | AG10: 0 | AH10: 12 | AI10: 0.15 | AJ10: 1 | AK10: 1 | AL10: 0 | AM10: 60 | AN10: 0 | AO10: 0 | AP10: 0 | AQ10: N | AR10: 0 | AS10: City water/sewer; zoning allows attached SF; near retail | AT10: Placeholder values
A11: Ranchette / acreage lots | B11: Housing | C11: For-Sale | D11: lot | E11: Y | F11: 0.2 | G11: 0 | H11: Y | I11: N | J11: N | K11: Y | L11: 0 | M11: 0 | N11: 0.05 | O11: 150 | P11: 0 | Q11: 1 | R11: 1 | S11: 10000 | T11: 0 | U11: 90000 | V11: 0 | W11: 0 | X11: 0 | Y11: 0 | Z11: 0 | AA11: 0 | AB11: 0 | AC11: 0 | AD11: 0 | AE11: 0.07 | AF11: 0 | AG11: 0 | AH11: 12 | AI11: 0.15 | AJ11: 1 | AK11: 0 | AL11: 0 | AM11: 60 | AN11: 0 | AO11: 0 | AP11: 0 | AQ11: N | AR11: 0 | AS11: Rural; good road frontage for flag-free lots; low flood exposure | AT11: Placeholder values
A12: Garage / car condos | B12: Storage | C12: For-Sale | D12: condo | E12: Y | F12: 0 | G12: 2900 | H12: N | I12: N | J12: N | K12: Y | L12: 0 | M12: 0 | N12: 0.05 | O12: 8 | P12: 900 | Q12: 0.1 | R12: 0.1 | S12: 25000 | T12: 85000 | U12: 0 | V12: 135000 | W12: 0 | X12: 0 | Y12: 0 | Z12: 0 | AA12: 0 | AB12: 0 | AC12: 0 | AD12: 0 | AE12: 0.07 | AF12: 0 | AG12: 0 | AH12: 12 | AI12: 0.15 | AJ12: 0 | AK12: 1 | AL12: 0 | AM12: 100 | AN12: 0 | AO12: 0 | AP12: 0 | AQ12: N | AR12: 0 | AS12: Affluent submarket; near lakes/airports; visible frontage | AT12: Placeholder values
A13: Contractor shop condos | B13: Business & Trades | C13: For-Sale | D13: condo (2,000 SF) | E13: Y | F13: 0 | G13: 5700 | H13: N | I13: N | J13: N | K13: Y | L13: 0 | M13: 6 | N13: 0.05 | O13: 10 | P13: 2500 | Q13: 0.2 | R13: 0.2 | S13: 25000 | T13: 190000 | U13: 0 | V13: 280000 | W13: 0 | X13: 0 | Y13: 0 | Z13: 0 | AA13: 0 | AB13: 0 | AC13: 0 | AD13: 0 | AE13: 0.07 | AF13: 0 | AG13: 0 | AH13: 12 | AI13: 0.15 | AJ13: 0 | AK13: 1 | AL13: 0 | AM13: 150 | AN13: 0 | AO13: 0 | AP13: 0 | AQ13: N | AR13: 0 | AS13: Arterial access; trades demand; light industrial / commercial zoning or county | AT13: Placeholder values
A14: Professional office condos | B14: Business & Trades | C14: For-Sale | D14: condo (1,500 SF) | E14: Y | F14: 0 | G14: 6000 | H14: N | I14: N | J14: Y | K14: Y | L14: 0 | M14: 4 | N14: 0.05 | O14: 8 | P14: 3000 | Q14: 0.25 | R14: 0.25 | S14: 25000 | T14: 300000 | U14: 0 | V14: 450000 | W14: 0 | X14: 0 | Y14: 0 | Z14: 0 | AA14: 0 | AB14: 0 | AC14: 0 | AD14: 0 | AE14: 0.07 | AF14: 0 | AG14: 0 | AH14: 12 | AI14: 0.15 | AJ14: 0 | AK14: 1 | AL14: 0 | AM14: 150 | AN14: 0 | AO14: 0 | AP14: 0 | AQ14: N | AR14: 0 | AS14: Near rooftops and medical/retail; commercial zoning | AT14: Placeholder values
A15: Manufactured home community (MHC) | B15: Housing | C15: Income | D15: pad | E15: Y | F15: 7 | G15: 0 | H15: Y | I15: N | J15: N | K15: Y | L15: 5 | M15: 0 | N15: 0.05 | O15: 40 | P15: 0 | Q15: 1 | R15: 1 | S15: 40000 | T15: 12000 | U15: 0 | V15: 0 | W15: 6600 | X15: 0.05 | Y15: 0.07 | Z15: 1200 | AA15: 0.05 | AB15: 0.15 | AC15: 0 | AD15: 24 | AE15: 0.065 | AF15: 40000 | AG15: 0 | AH15: 12 | AI15: 0.15 | AJ15: 1 | AK15: 1 | AL15: 1 | AM15: 60 | AN15: 0 | AO15: 0 | AP15: 0 | AQ15: N | AR15: 0 | AS15: County jurisdiction or MHC zoning; sewer or package plant for density; workforce job growth | AT15: Pad-only model. Park-owned homes = add home cost to vertical and home rent to rent (dealer-cost edge)
A16: Workforce / extended-stay RV park | B16: Housing | C16: Income | D16: site | E16: Y | F16: 15 | G16: 0 | H16: N | I16: N | J16: N | K16: Y | L16: 5 | M16: 0 | N16: 0.05 | O16: 30 | P16: 0 | Q16: 0.25 | R16: 0.25 | S16: 40000 | T16: 18000 | U16: 0 | V16: 0 | W16: 7800 | X16: 0.05 | Y16: 0.15 | Z16: 1800 | AA16: 0.08 | AB16: 0 | AC16: 0 | AD16: 12 | AE16: 0.085 | AF16: 40000 | AG16: 0 | AH16: 10 | AI16: 0.15 | AJ16: 1 | AK16: 1 | AL16: 1 | AM16: 60 | AN16: 0 | AO16: 0 | AP16: 0 | AQ16: N | AR16: 0 | AS16: Within 15 min of major construction/industrial employers (e.g. Sherman fabs); highway access | AT16: Placeholder values
... A57: Powered land for data centers | B57: Infrastructure | C57: Land Play | D57: acre | E57: N | F57: 0 | G57: 43560 | H57: N | I57: N | J57: N | K57: N | L57: 50 | M57: 0 | N57: 0.05 | O57: 0 | P57: 0 | Q57: 0 | R57: 0 | S57: 500000 | T57: 0 | U57: 0 | V57: 0 | W57: 0 | X57: 0 | Y57: 0 | Z57: 0 | AA57: 0 | AB57: 0 | AC57: 0 | AD57: 0 | AE57: 0.07 | AF57: 200000 | AG57: 0 | AH57: 24 | AI57: 0.25 | AJ57: 1 | AK57: 0 | AL57: 0 | AM57: 100 | AN57: 0 | AO57: 0 | AP57: 0 | AQ57: N | AR57: 1 | AS57: Transmission line / substation with available MW; fiber; water; 50+ ac | AT57: Entitlement = power/utility studies and agreements; the power commitment is the value

Sheet Engine
A1: Engine - every use run against this parcel
A2: One row per use, one column per calculation step, left to right. This tab IS the spec: each column header is a step Ryan codes. Do not edit - change inputs on Parcel, Assumptions, Use_Library.
A4: Identity | D4: Yield | W4: Quantities | AH4: Horizontal budget | BG4: Vertical | BJ4: Land & financing factors | BN4: Exit 1 - Land / pad sale | BT4: Build cost (exits 2 & 3) | BW4: Income (Income engine) | CG4: Exit 2 - Build & sell | CK4: Exit 3 - Build & hold / lease | CR4: Hold financing (Income) | CV4: Answer
A5: Use | B5: Engine | C5: Capacity unit | D5: Usable acres (net - open space - detention) | E5: Usable acres used by this use (market cap) | F5: Share of parcel used | G5: Net acres in use | H5: Detention acres | I5: Developed acres | J5: Excess gross acres (resold as raw land) | K5: Sewer requirement met (1/0) | L5: Water requirement met (1/0) | M5: Location test failures | N5: Location passes (1/0) | O5: Parcel big enough (1/0) | P5: Capacity by density | Q5: Capacity by site area | R5: Capacity by septic lot size | S5: CAPACITY (units / SF / acres) | T5: Binding constraint | U5: Anything fits (1/0) | V5: Horizontal by us (1/0) | W5: Internal road LF | X5: Paving / hardscape SF | Y5: Water line LF | Z5: Water taps | AA5: Sewer line LF | AB5: Sewer taps | AC5: Septic systems | AD5: Private wells | AE5: Acres to clear | AF5: Acres to grade | AG5: Lots to plat | AH5: 02-100 Survey | AI5: 02-110 Platting | AJ5: 02-200 Civil engineering | AK5: 02-300 Geotech | AL5: 02-310 Septic evaluations | AM5: 02-400 Phase I | AN5: 02-500 Drainage study | AO5: Entitlement & zoning (use-specific) | AP5: 02-700 Legal & title | AQ5: 03-100 Clearing | AR5: 03-200 Grading | AS5: 03-300 Roads / drives | AT5: 03-350 Paving / parking | AU5: 03-400 Detention | AV5: 03-500 SWPPP | AW5: 04-100 Water line | AX5: 04-110 Water taps | AY5: 04-200 Sewer line | AZ5: 04-210 Sewer taps | BA5: 04-300 Septic systems | BB5: 04-310 Wells | BC5: 04-400 Electric | BD5: Horizontal subtotal | BE5: Horizontal contingency | BF5: HORIZONTAL TOTAL (ex land) | BG5: Vertical hard cost | BH5: Vertical soft + contingency | BI5: TI + leasing commissions | BJ5: Land cost factor (closing + carry) | BK5: Financing factor - no lease-up | BL5: Financing factor - with lease-up | BM5: Excess land resale (net) | BN5: Exit 1 net revenue | BO5: Exit 1 non-land cost (no parking paving: buyer builds it) | BP5: Exit 1 cost per $1 of land | BQ5: Exit 1 total cost at asking | BR5: Exit 1 profit at asking | BS5: EXIT 1 MAX OFFER | BT5: Build non-land cost (pre-financing) | BU5: Build cost per $1 of land | BV5: Build total cost at asking | BW5: Gross potential rent | BX5: Effective gross income | BY5: Operating expenses (ex tax, ex mgmt) | BZ5: Property tax | CA5: Management | CB5: Expense recoveries | CC5: NET OPERATING INCOME | CD5: Stabilized value (NOI / cap) | CE5: Change in NOI per $1 of land | CF5: Yield on cost | CG5: Exit 2 net revenue | CH5: Change in exit 2 revenue per $1 of land | CI5: Exit 2 profit at asking | CJ5: EXIT 2 MAX OFFER | CK5: Exit 3 value | CL5: Exit 3 non-land cost | CM5: Exit 3 cost per $1 of land | CN5: Exit 3 total cost at asking | CO5: Change in exit 3 value per $1 of land | CP5: Exit 3 value created at asking | CQ5: EXIT 3 MAX OFFER | CR5: Development loan | CS5: Permanent loan (lesser of LTV, DSCR, debt yield) | CT5: DSCR on permanent loan | CU5: Cash out at refi (perm - dev loan) | CV5: BEST MAX OFFER | CW5: Best exit | CX5: Opening offer | CY5: Max offer minus asking | CZ5: Max offer per gross acre | DA5: Max offer per unit of capacity | DB5: Flags | DC5: Rank key
A6: =Use_Library!$A$5 -> Homesites (stick-built, for sale) | B6: =Use_Library!$C$5 -> For-Sale | C6: =Use_Library!$D$5 -> lot / home | D6: =MAX(0,Parcel!$C$26*(1-Use_Library!$N$5-Assumptions!$C$7)) -> 14.196 | E6: =IF(Use_Library!$M$5>0,MIN(D6,Use_Library!$M$5),D6) -> 14.196 | F6: =IF(D6=0,0,E6/D6) -> 1 | G6: =Parcel!$C$26*F6 -> 15.6 | H6: =G6*Assumptions!$C$7 -> 0.624 | I6: =G6*(1-Use_Library!$N$5) -> 14.82 | J6: =Parcel!$C$8*(1-F6) -> 0 | K6: =IF(AND(Use_Library!$I$5="Y",Parcel!$C$28=0),0,1) -> 1 | L6: =IF(AND(Use_Library!$J$5="Y",Parcel!$C$27=0),0,1) -> 1 | M6: =TRIM(IF(AND(Use_Library!$AN$5>0,Parcel!$C$19<Use_Library!$AN$5),"Traffic under "&TEXT(Use_Library!$AN$5,"#,##0")&" VPD. ","")&IF(AND(Use_Library!$AO$5>0,Parcel!$C$20<Use_Library!$AO$5),"Under "&TEXT(Use_Library!$AO$5,"#,##0")&" households in 3 mi. ","")&IF(AND(Use_Library!$AP$5>0,Parcel!$C$21>Use_Library!$AP$5),"Over "&Use_Library!$AP$5&" mi to highway. ","")&IF(AND(Use_Library!$AQ$5="Y",Parcel!$C$22<>"Y"),"Needs a corner. ","")&IF(AND(Use_Library!$AR$5>0,Parcel!$C$23>Use_Library!$AR$5),"Over "&Use_Library!$AR$5&" mi to substation. ","")) | N6: =IF(M6="",1,0) -> 1 | O6: =IF(D6>=Use_Library!$L$5,1,0) -> 1 | P6: =IF(Use_Library!$F$5>0,G6*Use_Library!$F$5,1000000000) -> 62.4 | Q6: =IF(Use_Library!$G$5>0,E6*43560/Use_Library!$G$5,1000000000) -> 1000000000 | R6: =IF(AND(Use_Library!$H$5="Y",Parcel!$C$28=0),E6*(1-Assumptions!$C$8)/IF(Parcel!$C$27=1,Assumptions!$C$9,Assumptions!$C$10),1000000000) -> 24.1332 | S6: =IF(K6*L6*O6*N6=0,0,IF(MIN(P6,Q6,R6)>=1000000000,E6,IF(Use_Library!$E$5="Y",INT(MIN(P6,Q6,R6)),MIN(P6,Q6,R6)))) -> 24 | T6: =IF(N6=0,"Location fails",IF(O6=0,"Too small - needs "&Use_Library!$L$5&" usable ac",IF(K6=0,"Needs public sewer",IF(L6=0,"Needs public water",IF(R6<=MIN(P6,Q6),"Septic lot size",IF(Q6<=P6,"Site area / parking","Density")))))) -> Septic lot size | U6: =IF(S6>0,1,0) -> 1 | V6: =IF(Use_Library!$K$5="Y",1,0)*U6 -> 1 | W6: =S6*Use_Library!$O$5*V6 -> 1200 | X6: =S6*Use_Library!$P$5*V6 -> 0 | Y6: =IF(Parcel!$C$27=1,W6+Parcel!$C$29,0)*V6 -> 1200 | Z6: =S6*Use_Library!$Q$5*Parcel!$C$27*V6 -> 24 | AA6: =IF(Parcel!$C$28=1,W6+Parcel!$C$30,0)*V6 -> 0 | AB6: =S6*Use_Library!$Q$5*Parcel!$C$28*V6 -> 0 | AC6: =IF(Parcel!$C$28=0,S6*Use_Library!$R$5,0)*V6 -> 24 | AD6: =IF(Parcel!$C$27=0,S6*Use_Library!$R$5,0)*V6 -> 0 | AE6: =I6*Parcel!$C$11*V6 -> 5.187 | AF6: =I6*V6 -> 14.82 | AG6: =IF(Use_Library!$C$5="For-Sale",IF(Use_Library!$E$5="Y",S6,1),1)*U6 -> 24 | AH6: =Cost_Library!$G$5*Parcel!$C$32*U6 -> 6500 | AI6: =AG6*Cost_Library!$G$6*Parcel!$C$32 -> 21600 | AJ6: =I6*Cost_Library!$G$7*Parcel!$C$32*V6 -> 74100 | AK6: =Cost_Library!$G$8*Parcel!$C$32*V6 -> 5000 | AL6: =AC6*Cost_Library!$G$9*Parcel!$C$32 -> 12000 | AM6: =Cost_Library!$G$10*U6 -> 2800 | AN6: =Cost_Library!$G$11*Parcel!$C$32*V6 -> 7500 | AO6: =Use_Library!$S$5*U6 -> 25000 | AP6: =Cost_Library!$G$12*U6 -> 10000 | AQ6: =AE6*Cost_Library!$G$13*Parcel!$C$32 -> 20748 | AR6: =AF6*Cost_Library!$G$14*Parcel!$C$32*Parcel!$C$33 -> 74100 | AS6: =W6*Cost_Library!$G$15*Parcel!$C$32 -> 180000 | AT6: =X6*Cost_Library!$G$16*Parcel!$C$32 -> 0 | AU6: =H6*Cost_Library!$G$17*Parcel!$C$32*V6 -> 34320 | AV6: =G6*Cost_Library!$G$18*Parcel!$C$32*V6 -> 10920 | AW6: =Y6*Cost_Library!$G$19*Parcel!$C$32 -> 60000 | AX6: =Z6*Cost_Library!$G$20 -> 60000 | AY6: =AA6*Cost_Library!$G$21*Parcel!$C$32 -> 0 | AZ6: =AB6*Cost_Library!$G$22 -> 0 | BA6: =AC6*Cost_Library!$G$23*Parcel!$C$32*Parcel!$C$34 -> 316800 | BB6: =AD6*Cost_Library!$G$24*Parcel!$C$32 -> 0 | BC6: =W6*Cost_Library!$G$25*Parcel!$C$32 -> 30000 | BD6: =SUM(AH6:BC6) -> 951388 | BE6: =BD6*Assumptions!$C$11 -> 95138.8 | BF6: =BD6+BE6 -> 1046526.8 | BG6: =S6*Use_Library!$T$5 -> 5880000 | BH6: =BG6*(Assumptions!$C$12+Assumptions!$C$13) -> 764400 | BI6: =S6*Use_Library!$AC$5 -> 0 | BJ6: =1+Assumptions!$C$14+Assumptions!$C$15*Use_Library!$AH$5/12 -> 1.045 | BK6: =1+Assumptions!$C$21*(Assumptions!$C$22*Use_Library!$AH$5/12*Assumptions!$C$24+Assumptions!$C$23) -> 1.038675 | BL6: =1+Assumptions!$C$21*(Assumptions!$C$22*(Use_Library!$AH$5/12*Assumptions!$C$24+IF(Use_Library!$C$5="Income",Use_Library!$AD$5,0)/12*Assumptions!$C$25)+Assumptions!$C$23) -> 1.038675 | BM6: =J6*Assumptions!$C$31*(1-Assumptions!$C$17)*U6 -> 0 | BN6: =IF(Use_Library!$AJ$5=1,IF(Use_Library!$C$5="For-Sale",S6*Use_Library!$U$5,E6*Use_Library!$AF$5)*(1-Assumptions!$C$17)+BM6,0)*U6 -> 1843200 | BO6: =(BD6-AT6)*(1+Assumptions!$C$11) -> 1046526.8 | BP6: =BJ6*BK6 -> 1.0854154 | BQ6: =(Parcel!$C$18*BJ6+BO6)*BK6 -> 1412625.8 | BR6: =BN6-BQ6 -> 430574.16 | BS6: =IF(AND(Use_Library!$AJ$5=1,U6=1),MAX(0,((1-Use_Library!$AI$5)*BN6-BO6*BK6)/BP6),0) -> 441967.92 | BT6: =BF6+BG6+BH6+BI6 -> 7690926.8 | BU6: =BJ6*BL6 -> 1.0854154 | BV6: =(Parcel!$C$18*BJ6+BT6)*BL6 -> 8313998 | BW6: =IF(Use_Library!$C$5="Income",S6*Use_Library!$W$5,0) -> 0 | BX6: =BW6*(1+Use_Library!$X$5)*(1-Use_Library!$Y$5) -> 0 | BY6: =IF(Use_Library!$C$5="Income",S6*Use_Library!$Z$5,0) -> 0 | BZ6: =IF(Use_Library!$C$5="Income",Assumptions!$C$19*Assumptions!$C$20*BV6,0) -> 0 | CA6: =BX6*Use_Library!$AA$5 -> 0 | CB6: =(BY6+BZ6)*Use_Library!$AB$5 -> 0 | CC6: =BX6-BY6-BZ6-CA6+CB6 -> 0 | CD6: =IF(AND(Use_Library!$C$5="Income",Use_Library!$AE$5>0),CC6/Use_Library!$AE$5,0) -> 0 | CE6: =IF(Use_Library!$C$5="Income",-Assumptions!$C$19*Assumptions!$C$20*(1-Use_Library!$AB$5)*BU6,0) -> 0 | CF6: =IF(BV6=0,0,CC6/BV6) -> 0 | CG6: =IF(Use_Library!$AK$5=1,IF(Use_Library!$C$5="Income",CD6*(1-Assumptions!$C$18),S6*Use_Library!$V$5*(1-Assumptions!$C$16))+BM6,0)*U6 -> 8460000 | CH6: =IF(AND(Use_Library!$AK$5=1,Use_Library!$C$5="Income",Use_Library!$AE$5>0),CE6/Use_Library!$AE$5*(1-Assumptions!$C$18),0) -> 0 | CI6: =CG6-BV6 -> 146001.99 | CJ6: =IF(AND(Use_Library!$AK$5=1,U6=1),MAX(0,Parcel!$C$18-((1-Use_Library!$AI$5)*CG6-BV6)/((1-Use_Library!$AI$5)*CH6-BU6)),0) -> 0 | CK6: =IF(Use_Library!$AL$5=1,IF(Use_Library!$C$5="Income",CD6,IF(Use_Library!$AE$5>0,E6*Use_Library!$AG$5/Use_Library!$AE$5,0))+BM6,0)*U6 -> 0 | CL6: =IF(Use_Library!$C$5="Income",BT6,BF6) -> 1046526.8 | CM6: =IF(Use_Library!$C$5="Income",BU6,BJ6*BK6) -> 1.0854154 | CN6: =IF(Use_Library!$C$5="Income",BV6,(Parcel!$C$18*BJ6+BF6)*BK6) -> 1412625.8 | CO6: =IF(AND(Use_Library!$AL$5=1,Use_Library!$C$5="Income",Use_Library!$AE$5>0),CE6/Use_Library!$AE$5,0) -> 0 | CP6: =CK6-CN6 -> -1412625.8 | CQ6: =IF(AND(Use_Library!$AL$5=1,U6=1),MAX(0,Parcel!$C$18-((1-Use_Library!$AI$5)*CK6-CN6)/((1-Use_Library!$AI$5)*CO6-CM6)),0) -> 0 | CR6: =IF(Use_Library!$C$5="Income",Assumptions!$C$21*(Parcel!$C$18*BJ6+BT6),0) -> 0 | CS6: =IF(AND(Use_Library!$C$5="Income",CC6>0),MIN(Assumptions!$C$26*CD6,PV(Assumptions!$C$29/12,Assumptions!$C$30*12,-CC6/Assumptions!$C$27/12),CC6/Assumptions!$C$28),0) -> 0 | CT6: =IF(CS6=0,0,CC6/(-PMT(Assumptions!$C$29/12,Assumptions!$C$30*12,CS6)*12)) -> 0 | CU6: =CS6-CR6 -> 0 | CV6: =MAX(BS6,CJ6,CQ6) -> 441967.92 | CW6: =IF(CV6<=0,"None works",IF(BS6=CV6,"Land / pad sale",IF(CJ6=CV6,"Build & sell","Build & hold / lease"))) -> Land / pad sale | CX6: =CV6*(1-Assumptions!$C$32) -> 375672.73 | CY6: =CV6-Parcel!$C$18 -> 141967.92 | CZ6: =IF(Parcel!$C$8=0,0,CV6/Parcel!$C$8) -> 22098.396 | DA6: =IF(S6=0,0,CV6/S6) -> 18415.33 | DB6: =TRIM(M6&" "&IF(AND(U6=0,N6=1),"Nothing fits. ","")&IF(Parcel!$C$12<Use_Library!$AM$5,"Frontage under "&Use_Library!$AM$5&" LF. ","")&IF(Parcel!$C$10>0.15,"Slope over 15%. ","")&IF(AND(U6=1,Use_Library!$M$5>0,D6>Use_Library!$M$5),"Only "&Use_Library!$M$5&" ac used - rest resold. ","")) | DC6: =CV6+ROW()/1000000 -> 441967.92
A7: =Use_Library!$A$6 -> Finished / entitled lots | B7: =Use_Library!$C$6 -> For-Sale | C7: =Use_Library!$D$6 -> lot | D7: =MAX(0,Parcel!$C$26*(1-Use_Library!$N$6-Assumptions!$C$7)) -> 14.196 | E7: =IF(Use_Library!$M$6>0,MIN(D7,Use_Library!$M$6),D7) -> 14.196 | F7: =IF(D7=0,0,E7/D7) -> 1 | G7: =Parcel!$C$26*F7 -> 15.6 | H7: =G7*Assumptions!$C$7 -> 0.624 | I7: =G7*(1-Use_Library!$N$6) -> 14.82 | J7: =Parcel!$C$8*(1-F7) -> 0 | K7: =IF(AND(Use_Library!$I$6="Y",Parcel!$C$28=0),0,1) -> 1 | L7: =IF(AND(Use_Library!$J$6="Y",Parcel!$C$27=0),0,1) -> 1 | M7: =TRIM(IF(AND(Use_Library!$AN$6>0,Parcel!$C$19<Use_Library!$AN$6),"Traffic under "&TEXT(Use_Library!$AN$6,"#,##0")&" VPD. ","")&IF(AND(Use_Library!$AO$6>0,Parcel!$C$20<Use_Library!$AO$6),"Under "&TEXT(Use_Library!$AO$6,"#,##0")&" households in 3 mi. ","")&IF(AND(Use_Library!$AP$6>0,Parcel!$C$21>Use_Library!$AP$6),"Over "&Use_Library!$AP$6&" mi to highway. ","")&IF(AND(Use_Library!$AQ$6="Y",Parcel!$C$22<>"Y"),"Needs a corner. ","")&IF(AND(Use_Library!$AR$6>0,Parcel!$C$23>Use_Library!$AR$6),"Over "&Use_Library!$AR$6&" mi to substation. ","")) | N7: =IF(M7="",1,0) -> 1 | O7: =IF(D7>=Use_Library!$L$6,1,0) -> 1 | P7: =IF(Use_Library!$F$6>0,G7*Use_Library!$F$6,1000000000) -> 62.4 | Q7: =IF(Use_Library!$G$6>0,E7*43560/Use_Library!$G$6,1000000000) -> 1000000000 | R7: =IF(AND(Use_Library!$H$6="Y",Parcel!$C$28=0),E7*(1-Assumptions!$C$8)/IF(Parcel!$C$27=1,Assumptions!$C$9,Assumptions!$C$10),1000000000) -> 24.1332 | S7: =IF(K7*L7*O7*N7=0,0,IF(MIN(P7,Q7,R7)>=1000000000,E7,IF(Use_Library!$E$6="Y",INT(MIN(P7,Q7,R7)),MIN(P7,Q7,R7)))) -> 24 | T7: =IF(N7=0,"Location fails",IF(O7=0,"Too small - needs "&Use_Library!$L$6&" usable ac",IF(K7=0,"Needs public sewer",IF(L7=0,"Needs public water",IF(R7<=MIN(P7,Q7),"Septic lot size",IF(Q7<=P7,"Site area / parking","Density")))))) -> Septic lot size | U7: =IF(S7>0,1,0) -> 1 | V7: =IF(Use_Library!$K$6="Y",1,0)*U7 -> 1 | W7: =S7*Use_Library!$O$6*V7 -> 1200 | X7: =S7*Use_Library!$P$6*V7 -> 0 | Y7: =IF(Parcel!$C$27=1,W7+Parcel!$C$29,0)*V7 -> 1200 | Z7: =S7*Use_Library!$Q$6*Parcel!$C$27*V7 -> 24 | AA7: =IF(Parcel!$C$28=1,W7+Parcel!$C$30,0)*V7 -> 0 | AB7: =S7*Use_Library!$Q$6*Parcel!$C$28*V7 -> 0 | AC7: =IF(Parcel!$C$28=0,S7*Use_Library!$R$6,0)*V7 -> 24 | AD7: =IF(Parcel!$C$27=0,S7*Use_Library!$R$6,0)*V7 -> 0 | AE7: =I7*Parcel!$C$11*V7 -> 5.187 | AF7: =I7*V7 -> 14.82 | AG7: =IF(Use_Library!$C$6="For-Sale",IF(Use_Library!$E$6="Y",S7,1),1)*U7 -> 24 | AH7: =Cost_Library!$G$5*Parcel!$C$32*U7 -> 6500 | AI7: =AG7*Cost_Library!$G$6*Parcel!$C$32 -> 21600 | AJ7: =I7*Cost_Library!$G$7*Parcel!$C$32*V7 -> 74100 | AK7: =Cost_Library!$G$8*Parcel!$C$32*V7 -> 5000 | AL7: =AC7*Cost_Library!$G$9*Parcel!$C$32 -> 12000 | AM7: =Cost_Library!$G$10*U7 -> 2800 | AN7: =Cost_Library!$G$11*Parcel!$C$32*V7 -> 7500 | AO7: =Use_Library!$S$6*U7 -> 25000 | AP7: =Cost_Library!$G$12*U7 -> 10000 | AQ7: =AE7*Cost_Library!$G$13*Parcel!$C$32 -> 20748 | AR7: =AF7*Cost_Library!$G$14*Parcel!$C$32*Parcel!$C$33 -> 74100 | AS7: =W7*Cost_Library!$G$15*Parcel!$C$32 -> 180000 | AT7: =X7*Cost_Library!$G$16*Parcel!$C$32 -> 0 | AU7: =H7*Cost_Library!$G$17*Parcel!$C$32*V7 -> 34320 | AV7: =G7*Cost_Library!$G$18*Parcel!$C$32*V7 -> 10920 | AW7: =Y7*Cost_Library!$G$19*Parcel!$C$32 -> 60000 | AX7: =Z7*Cost_Library!$G$20 -> 60000 | AY7: =AA7*Cost_Library!$G$21*Parcel!$C$32 -> 0 | AZ7: =AB7*Cost_Library!$G$22 -> 0 | BA7: =AC7*Cost_Library!$G$23*Parcel!$C$32*Parcel!$C$34 -> 316800 | BB7: =AD7*Cost_Library!$G$24*Parcel!$C$32 -> 0 | BC7: =W7*Cost_Library!$G$25*Parcel!$C$32 -> 30000 | BD7: =SUM(AH7:BC7) -> 951388 | BE7: =BD7*Assumptions!$C$11 -> 95138.8 | BF7: =BD7+BE7 -> 1046526.8 | BG7: =S7*Use_Library!$T$6 -> 0 | BH7: =BG7*(Assumptions!$C$12+Assumptions!$C$13) -> 0 | BI7: =S7*Use_Library!$AC$6 -> 0 | BJ7: =1+Assumptions!$C$14+Assumptions!$C$15*Use_Library!$AH$6/12 -> 1.045 | BK7: =1+Assumptions!$C$21*(Assumptions!$C$22*Use_Library!$AH$6/12*Assumptions!$C$24+Assumptions!$C$23) -> 1.038675 | BL7: =1+Assumptions!$C$21*(Assumptions!$C$22*(Use_Library!$AH$6/12*Assumptions!$C$24+IF(Use_Library!$C$6="Income",Use_Library!$AD$6,0)/12*Assumptions!$C$25)+Assumptions!$C$23) -> 1.038675 | BM7: =J7*Assumptions!$C$31*(1-Assumptions!$C$17)*U7 -> 0 | BN7: =IF(Use_Library!$AJ$6=1,IF(Use_Library!$C$6="For-Sale",S7*Use_Library!$U$6,E7*Use_Library!$AF$6)*(1-Assumptions!$C$17)+BM7,0)*U7 -> 1728000 | BO7: =(BD7-AT7)*(1+Assumptions!$C$11) -> 1046526.8 | BP7: =BJ7*BK7 -> 1.0854154 | BQ7: =(Parcel!$C$18*BJ7+BO7)*BK7 -> 1412625.8 | BR7: =BN7-BQ7 -> 315374.16 | BS7: =IF(AND(Use_Library!$AJ$6=1,U7=1),MAX(0,((1-Use_Library!$AI$6)*BN7-BO7*BK7)/BP7),0) -> 351753.61 | BT7: =BF7+BG7+BH7+BI7 -> 1046526.8 | BU7: =BJ7*BL7 -> 1.0854154 | BV7: =(Parcel!$C$18*BJ7+BT7)*BL7 -> 1412625.8 | BW7: =IF(Use_Library!$C$6="Income",S7*Use_Library!$W$6,0) -> 0 | BX7: =BW7*(1+Use_Library!$X$6)*(1-Use_Library!$Y$6) -> 0 | BY7: =IF(Use_Library!$C$6="Income",S7*Use_Library!$Z$6,0) -> 0 | BZ7: =IF(Use_Library!$C$6="Income",Assumptions!$C$19*Assumptions!$C$20*BV7,0) -> 0 | CA7: =BX7*Use_Library!$AA$6 -> 0 | CB7: =(BY7+BZ7)*Use_Library!$AB$6 -> 0 | CC7: =BX7-BY7-BZ7-CA7+CB7 -> 0 | CD7: =IF(AND(Use_Library!$C$6="Income",Use_Library!$AE$6>0),CC7/Use_Library!$AE$6,0) -> 0 | CE7: =IF(Use_Library!$C$6="Income",-Assumptions!$C$19*Assumptions!$C$20*(1-Use_Library!$AB$6)*BU7,0) -> 0 | CF7: =IF(BV7=0,0,CC7/BV7) -> 0 | CG7: =IF(Use_Library!$AK$6=1,IF(Use_Library!$C$6="Income",CD7*(1-Assumptions!$C$18),S7*Use_Library!$V$6*(1-Assumptions!$C$16))+BM7,0)*U7 -> 0 | CH7: =IF(AND(Use_Library!$AK$6=1,Use_Library!$C$6="Income",Use_Library!$AE$6>0),CE7/Use_Library!$AE$6*(1-Assumptions!$C$18),0) -> 0 | CI7: =CG7-BV7 -> -1412625.8 | CJ7: =IF(AND(Use_Library!$AK$6=1,U7=1),MAX(0,Parcel!$C$18-((1-Use_Library!$AI$6)*CG7-BV7)/((1-Use_Library!$AI$6)*CH7-BU7)),0) -> 0 | CK7: =IF(Use_Library!$AL$6=1,IF(Use_Library!$C$6="Income",CD7,IF(Use_Library!$AE$6>0,E7*Use_Library!$AG$6/Use_Library!$AE$6,0))+BM7,0)*U7 -> 0 | CL7: =IF(Use_Library!$C$6="Income",BT7,BF7) -> 1046526.8 | CM7: =IF(Use_Library!$C$6="Income",BU7,BJ7*BK7) -> 1.0854154 | CN7: =IF(Use_Library!$C$6="Income",BV7,(Parcel!$C$18*BJ7+BF7)*BK7) -> 1412625.8 | CO7: =IF(AND(Use_Library!$AL$6=1,Use_Library!$C$6="Income",Use_Library!$AE$6>0),CE7/Use_Library!$AE$6,0) -> 0 | CP7: =CK7-CN7 -> -1412625.8 | CQ7: =IF(AND(Use_Library!$AL$6=1,U7=1),MAX(0,Parcel!$C$18-((1-Use_Library!$AI$6)*CK7-CN7)/((1-Use_Library!$AI$6)*CO7-CM7)),0) -> 0 | CR7: =IF(Use_Library!$C$6="Income",Assumptions!$C$21*(Parcel!$C$18*BJ7+BT7),0) -> 0 | CS7: =IF(AND(Use_Library!$C$6="Income",CC7>0),MIN(Assumptions!$C$26*CD7,PV(Assumptions!$C$29/12,Assumptions!$C$30*12,-CC7/Assumptions!$C$27/12),CC7/Assumptions!$C$28),0) -> 0 | CT7: =IF(CS7=0,0,CC7/(-PMT(Assumptions!$C$29/12,Assumptions!$C$30*12,CS7)*12)) -> 0 | CU7: =CS7-CR7 -> 0 | CV7: =MAX(BS7,CJ7,CQ7) -> 351753.61 | CW7: =IF(CV7<=0,"None works",IF(BS7=CV7,"Land / pad sale",IF(CJ7=CV7,"Build & sell","Build & hold / lease"))) -> Land / pad sale | CX7: =CV7*(1-Assumptions!$C$32) -> 298990.57 | CY7: =CV7-Parcel!$C$18 -> 51753.61 | CZ7: =IF(Parcel!$C$8=0,0,CV7/Parcel!$C$8) -> 17587.68 | DA7: =IF(S7=0,0,CV7/S7) -> 14656.4 | DB7: =TRIM(M7&" "&IF(AND(U7=0,N7=1),"Nothing fits. ","")&IF(Parcel!$C$12<Use_Library!$AM$6,"Frontage under "&Use_Library!$AM$6&" LF. ","")&IF(Parcel!$C$10>0.15,"Slope over 15%. ","")&IF(AND(U7=1,Use_Library!$M$6>0,D7>Use_Library!$M$6),"Only "&Use_Library!$M$6&" ac used - rest resold. ","")) | DC7: =CV7+ROW()/1000000 -> 351753.61
A8: =Use_Library!$A$7 -> Active-adult 55+ (for sale) | B8: =Use_Library!$C$7 -> For-Sale | C8: =Use_Library!$D$7 -> lot / home | D8: =MAX(0,Parcel!$C$26*(1-Use_Library!$N$7-Assumptions!$C$7)) -> 14.196 | E8: =IF(Use_Library!$M$7>0,MIN(D8,Use_Library!$M$7),D8) -> 14.196 | F8: =IF(D8=0,0,E8/D8) -> 1 | G8: =Parcel!$C$26*F8 -> 15.6 | H8: =G8*Assumptions!$C$7 -> 0.624 | I8: =G8*(1-Use_Library!$N$7) -> 14.82 | J8: =Parcel!$C$8*(1-F8) -> 0 | K8: =IF(AND(Use_Library!$I$7="Y",Parcel!$C$28=0),0,1) -> 1 | L8: =IF(AND(Use_Library!$J$7="Y",Parcel!$C$27=0),0,1) -> 1 | M8: =TRIM(IF(AND(Use_Library!$AN$7>0,Parcel!$C$19<Use_Library!$AN$7),"Traffic under "&TEXT(Use_Library!$AN$7,"#,##0")&" VPD. ","")&IF(AND(Use_Library!$AO$7>0,Parcel!$C$20<Use_Library!$AO$7),"Under "&TEXT(Use_Library!$AO$7,"#,##0")&" households in 3 mi. ","")&IF(AND(Use_Library!$AP$7>0,Parcel!$C$21>Use_Library!$AP$7),"Over "&Use_Library!$AP$7&" mi to highway. ","")&IF(AND(Use_Library!$AQ$7="Y",Parcel!$C$22<>"Y"),"Needs a corner. ","")&IF(AND(Use_Library!$AR$7>0,Parcel!$C$23>Use_Library!$AR$7),"Over "&Use_Library!$AR$7&" mi to substation. ","")) | N8: =IF(M8="",1,0) -> 1 | O8: =IF(D8>=Use_Library!$L$7,1,0) -> 1 | P8: =IF(Use_Library!$F$7>0,G8*Use_Library!$F$7,1000000000) -> 78 | Q8: =IF(Use_Library!$G$7>0,E8*43560/Use_Library!$G$7,1000000000) -> 1000000000 | R8: =IF(AND(Use_Library!$H$7="Y",Parcel!$C$28=0),E8*(1-Assumptions!$C$8)/IF(Parcel!$C$27=1,Assumptions!$C$9,Assumptions!$C$10),1000000000) -> 24.1332 | S8: =IF(K8*L8*O8*N8=0,0,IF(MIN(P8,Q8,R8)>=1000000000,E8,IF(Use_Library!$E$7="Y",INT(MIN(P8,Q8,R8)),MIN(P8,Q8,R8)))) -> 24 | T8: =IF(N8=0,"Location fails",IF(O8=0,"Too small - needs "&Use_Library!$L$7&" usable ac",IF(K8=0,"Needs public sewer",IF(L8=0,"Needs public water",IF(R8<=MIN(P8,Q8),"Septic lot size",IF(Q8<=P8,"Site area / parking","Density")))))) -> Septic lot size | U8: =IF(S8>0,1,0) -> 1 | V8: =IF(Use_Library!$K$7="Y",1,0)*U8 -> 1 | W8: =S8*Use_Library!$O$7*V8 -> 1080 | X8: =S8*Use_Library!$P$7*V8 -> 0 | Y8: =IF(Parcel!$C$27=1,W8+Parcel!$C$29,0)*V8 -> 1080 | Z8: =S8*Use_Library!$Q$7*Parcel!$C$27*V8 -> 24 | AA8: =IF(Parcel!$C$28=1,W8+Parcel!$C$30,0)*V8 -> 0 | AB8: =S8*Use_Library!$Q$7*Parcel!$C$28*V8 -> 0 | AC8: =IF(Parcel!$C$28=0,S8*Use_Library!$R$7,0)*V8 -> 24 | AD8: =IF(Parcel!$C$27=0,S8*Use_Library!$R$7,0)*V8 -> 0 | AE8: =I8*Parcel!$C$11*V8 -> 5.187 | AF8: =I8*V8 -> 14.82 | AG8: =IF(Use_Library!$C$7="For-Sale",IF(Use_Library!$E$7="Y",S8,1),1)*U8 -> 24 | AH8: =Cost_Library!$G$5*Parcel!$C$32*U8 -> 6500 | AI8: =AG8*Cost_Library!$G$6*Parcel!$C$32 -> 21600 | AJ8: =I8*Cost_Library!$G$7*Parcel!$C$32*V8 -> 74100 | AK8: =Cost_Library!$G$8*Parcel!$C$32*V8 -> 5000 | AL8: =AC8*Cost_Library!$G$9*Parcel!$C$32 -> 12000 | AM8: =Cost_Library!$G$10*U8 -> 2800 | AN8: =Cost_Library!$G$11*Parcel!$C$32*V8 -> 7500 | AO8: =Use_Library!$S$7*U8 -> 25000 | AP8: =Cost_Library!$G$12*U8 -> 10000 | AQ8: =AE8*Cost_Library!$G$13*Parcel!$C$32 -> 20748 | AR8: =AF8*Cost_Library!$G$14*Parcel!$C$32*Parcel!$C$33 -> 74100 | AS8: =W8*Cost_Library!$G$15*Parcel!$C$32 -> 162000 | AT8: =X8*Cost_Library!$G$16*Parcel!$C$32 -> 0 | AU8: =H8*Cost_Library!$G$17*Parcel!$C$32*V8 -> 34320 | AV8: =G8*Cost_Library!$G$18*Parcel!$C$32*V8 -> 10920 | AW8: =Y8*Cost_Library!$G$19*Parcel!$C$32 -> 54000 | AX8: =Z8*Cost_Library!$G$20 -> 60000 | AY8: =AA8*Cost_Library!$G$21*Parcel!$C$32 -> 0 | AZ8: =AB8*Cost_Library!$G$22 -> 0 | BA8: =AC8*Cost_Library!$G$23*Parcel!$C$32*Parcel!$C$34 -> 316800 | BB8: =AD8*Cost_Library!$G$24*Parcel!$C$32 -> 0 | BC8: =W8*Cost_Library!$G$25*Parcel!$C$32 -> 27000 | BD8: =SUM(AH8:BC8) -> 924388 | BE8: =BD8*Assumptions!$C$11 -> 92438.8 | BF8: =BD8+BE8 -> 1016826.8 | BG8: =S8*Use_Library!$T$7 -> 5520000 | BH8: =BG8*(Assumptions!$C$12+Assumptions!$C$13) -> 717600 | BI8: =S8*Use_Library!$AC$7 -> 0 | BJ8: =1+Assumptions!$C$14+Assumptions!$C$15*Use_Library!$AH$7/12 -> 1.045 | BK8: =1+Assumptions!$C$21*(Assumptions!$C$22*Use_Library!$AH$7/12*Assumptions!$C$24+Assumptions!$C$23) -> 1.038675 | BL8: =1+Assumptions!$C$21*(Assumptions!$C$22*(Use_Library!$AH$7/12*Assumptions!$C$24+IF(Use_Library!$C$7="Income",Use_Library!$AD$7,0)/12*Assumptions!$C$25)+Assumptions!$C$23) -> 1.038675 | BM8: =J8*Assumptions!$C$31*(1-Assumptions!$C$17)*U8 -> 0 | BN8: =IF(Use_Library!$AJ$7=1,IF(Use_Library!$C$7="For-Sale",S8*Use_Library!$U$7,E8*Use_Library!$AF$7)*(1-Assumptions!$C$17)+BM8,0)*U8 -> 1612800 | BO8: =(BD8-AT8)*(1+Assumptions!$C$11) -> 1016826.8 | BP8: =BJ8*BK8 -> 1.0854154 | BQ8: =(Parcel!$C$18*BJ8+BO8)*BK8 -> 1381777.2 | BR8: =BN8-BQ8 -> 231022.81 | BS8: =IF(AND(Use_Library!$AJ$7=1,U8=1),MAX(0,((1-Use_Library!$AI$7)*BN8-BO8*BK8)/BP8),0) -> 289960.35 | BT8: =BF8+BG8+BH8+BI8 -> 7254426.8 | BU8: =BJ8*BL8 -> 1.0854154 | BV8: =(Parcel!$C$18*BJ8+BT8)*BL8 -> 7860616.4 | BW8: =IF(Use_Library!$C$7="Income",S8*Use_Library!$W$7,0) -> 0 | BX8: =BW8*(1+Use_Library!$X$7)*(1-Use_Library!$Y$7) -> 0 | BY8: =IF(Use_Library!$C$7="Income",S8*Use_Library!$Z$7,0) -> 0 | BZ8: =IF(Use_Library!$C$7="Income",Assumptions!$C$19*Assumptions!$C$20*BV8,0) -> 0 | CA8: =BX8*Use_Library!$AA$7 -> 0 | CB8: =(BY8+BZ8)*Use_Library!$AB$7 -> 0 | CC8: =BX8-BY8-BZ8-CA8+CB8 -> 0 | CD8: =IF(AND(Use_Library!$C$7="Income",Use_Library!$AE$7>0),CC8/Use_Library!$AE$7,0) -> 0 | CE8: =IF(Use_Library!$C$7="Income",-Assumptions!$C$19*Assumptions!$C$20*(1-Use_Library!$AB$7)*BU8,0) -> 0 | CF8: =IF(BV8=0,0,CC8/BV8) -> 0 | CG8: =IF(Use_Library!$AK$7=1,IF(Use_Library!$C$7="Income",CD8*(1-Assumptions!$C$18),S8*Use_Library!$V$7*(1-Assumptions!$C$16))+BM8,0)*U8 -> 8121600 | CH8: =IF(AND(Use_Library!$AK$7=1,Use_Library!$C$7="Income",Use_Library!$AE$7>0),CE8/Use_Library!$AE$7*(1-Assumptions!$C$18),0) -> 0 | CI8: =CG8-BV8 -> 260983.63 | CJ8: =IF(AND(Use_Library!$AK$7=1,U8=1),MAX(0,Parcel!$C$18-((1-Use_Library!$AI$7)*CG8-BV8)/((1-Use_Library!$AI$7)*CH8-BU8)),0) -> 0 | CK8: =IF(Use_Library!$AL$7=1,IF(Use_Library!$C$7="Income",CD8,IF(Use_Library!$AE$7>0,E8*Use_Library!$AG$7/Use_Library!$AE$7,0))+BM8,0)*U8 -> 0 | CL8: =IF(Use_Library!$C$7="Income",BT8,BF8) -> 1016826.8 | CM8: =IF(Use_Library!$C$7="Income",BU8,BJ8*BK8) -> 1.0854154 | CN8: =IF(Use_Library!$C$7="Income",BV8,(Parcel!$C$18*BJ8+BF8)*BK8) -> 1381777.2 | CO8: =IF(AND(Use_Library!$AL$7=1,Use_Library!$C$7="Income",Use_Library!$AE$7>0),CE8/Use_Library!$AE$7,0) -> 0 | CP8: =CK8-CN8 -> -1381777.2 | CQ8: =IF(AND(Use_Library!$AL$7=1,U8=1),MAX(0,Parcel!$C$18-((1-Use_Library!$AI$7)*CK8-CN8)/((1-Use_Library!$AI$7)*CO8-CM8)),0) -> 0 | CR8: =IF(Use_Library!$C$7="Income",Assumptions!$C$21*(Parcel!$C$18*BJ8+BT8),0) -> 0 | CS8: =IF(AND(Use_Library!$C$7="Income",CC8>0),MIN(Assumptions!$C$26*CD8,PV(Assumptions!$C$29/12,Assumptions!$C$30*12,-CC8/Assumptions!$C$27/12),CC8/Assumptions!$C$28),0) -> 0 | CT8: =IF(CS8=0,0,CC8/(-PMT(Assumptions!$C$29/12,Assumptions!$C$30*12,CS8)*12)) -> 0 | CU8: =CS8-CR8 -> 0 | CV8: =MAX(BS8,CJ8,CQ8) -> 289960.35 | CW8: =IF(CV8<=0,"None works",IF(BS8=CV8,"Land / pad sale",IF(CJ8=CV8,"Build & sell","Build & hold / lease"))) -> Land / pad sale | CX8: =CV8*(1-Assumptions!$C$32) -> 246466.3 | CY8: =CV8-Parcel!$C$18 -> -10039.649 | CZ8: =IF(Parcel!$C$8=0,0,CV8/Parcel!$C$8) -> 14498.018 | DA8: =IF(S8=0,0,CV8/S8) -> 12081.681 | DB8: =TRIM(M8&" "&IF(AND(U8=0,N8=1),"Nothing fits. ","")&IF(Parcel!$C$12<Use_Library!$AM$7,"Frontage under "&Use_Library!$AM$7&" LF. ","")&IF(Parcel!$C$10>0.15,"Slope over 15%. ","")&IF(AND(U8=1,Use_Library!$M$7>0,D8>Use_Library!$M$7),"Only "&Use_Library!$M$7&" ac used - rest resold. ","")) | DC8: =CV8+ROW()/1000000 -> 289960.35
